Workbook

Sheet DAMASO
A1: DATOS BASICOS
A2: SISTEMA | B2: 1 | C2: 1=SEBD/2=SM
A3: SEXO | B3: M
A4: FECHA DE NACIMIENTO | B4: 22564
A5: FECHA DE PRIMERA CUOTA | B5: 29860
A6: EDAD ENTRADA | B6: =+DATEDIF(B4,B5,"Y") -> 19
A7: EDAD ACTUAL | B7: =2024-YEAR(B4) -> 63
A8: EDAD DE JUBILACION | B8: 65
A9: SALARIO MENSUAL HOY
A10: TASA CRECIMIENTO SALARIAL | B10: 0.015
A11: % CUOTA APLICADO ANTES VIGENCIA NVA LEY | B11: 0.15 | I11: BENEFICIO DE JUBILACION CSS | S11: BENEFICIO ACTUARIAL JUSTO
A12: % CUOTA EMPLEADO EMPLEADOR NUEVA LEY | B12: 0.15 | I12: CUOTAS APORTADAS | N12: =+SUM(AE29:AE77) -> 541 | S12: EDAD JUBILACION | X12: =+B8 -> 65
A13: % XIII EMPLEADO EMPLEADOR NUEVA LEY | B13: 0.15 | I13: CUOTAS EN EXCESO A DENSIDAD MIN | N13: =+N12-B16 -> 301 | S13: FONDO AHORRADO COP ANTES VIGENCIA NVA LEY | X13: =+VLOOKUP(X12,$J$29:$Q$77,8,FALSE) -> 217009.7
A14: TASA DE RETORNO INVERSIONES ANTES VIG LEY | B14: 0.04 | I14: TASA DE REEMPLAZO SEBD LEY 51 | N14: =+$B$17+INT(N13/12)*$B$18 -> 0.9125 | S14: FACTOR DESCUENTO | X14: =+IF($B$3="M",VLOOKUP(X12,descuento!$A$6:$B$32,2,FALSE),VLOOKUP(X12,descuento!$C$6:$D$32,2,FALSE)) -> 1
A15: TASA RETORNO INVERSIONES PROMEDIO | B15: 0.05 | I15: SALARIO PROMEDIO mejores 10 años | N15: =+VLOOKUP(N17,W20:X22,2,0) -> 30657.333 | S15: FONDO AHORRADO COP DESPUES VIGENCIA NVA LEY | X15: =+VLOOKUP(X12,$T$29:$AA$77,8,FALSE) -> 11502.345
A16: DENSIDAD MINIMA DE CUOTAS LEY 51 | B16: 240 | I16: PENSION ANNUAL A RECIBIR | N16: =+N17*12 -> 24000 | S16: FONDO TOTAL APLICABLE | X16: =+X15+X13*X14 -> 228512.05
A17: TASA DE REEMPLAZO INICIAL LEY 51 | B17: 0.6 | I17: PENSION MENSUAL A RECIBIR | N17: =+MAX(W20:W22) -> 2000 | S17: FACTOR PENSION X MIL | X17: =+VLOOKUP(X12,'bases renta'!$K$20:$L$65,2,FALSE) -> 5.4399911
A18: TASA DE REEMPLAZO ADICIONAL LEY 51 | B18: 0.0125 | I18: TASA DE REEMPLAZO SEBD LEY 51 | N18: =+N16/N15 -> 0.78284695 | S18: PENSION ACTUARIAL JUSTA MENSUAL | X18: =+X17*X16*0.001 -> 1243.1035
A19: SALMAX MENSUAL COTIZADO ANTES VIG NVA LEY | B19: 2500 | S19: PENSION ACTUARIAL ANNUAL JUSTA | X19: =+X18*12 -> 14917.242
A20: PENSION MAXIMA LEY51 | B20: 2500 | S20: PROMEDIO DE LOS MEJORES 10 AÑOS | W20: =+IF($N$14*X20/12>1500,1500,$N$14*X20/12) -> 1500 | X20: {=+AVERAGE(LARGE($AF$29:$AF$77,ROW(INDIRECT("1:10"))))} -> 31481.2
S21: PROMEDIO DE LOS MEJORES 15 AÑOS | W21: =+IF($N$14*X21/12>2000,2000,$N$14*X21/12) -> 2000 | X21: {=IF(AND(N12>300,AVERAGE(LARGE($AF$29:$AF$77,ROW(INDIRECT("1:15"))))>=24000),AVERAGE(LARGE($AF$29:$AF$77,ROW(INDIRECT("1:15")))),0)} -> 30657.333
S22: PROMEDIO DE LOS MEJORES 20 AÑOS | W22: =+IF($N$14*X22/12>2500,2500,$N$14*X22/12) -> 0 | X22: {=IF(AND(N12>360,AVERAGE(LARGE($AF$29:$AF$77,ROW(INDIRECT("1:20"))))>=30000),AVERAGE(LARGE($AF$29:$AF$77,ROW(INDIRECT("1:20")))),0)} -> 0
S24: TASA REEMPLAZO SISTEMA | X24: =+X19/VLOOKUP(N17,W20:X22,2,0) -> 0.48657989
I26: ACUMULACION ANTES VIGENCIA NUEVA LEY | S26: ACUMULACION DESPUES VIGENCIA NUEVA LEY | AC26: SALARIOS PARA CALCULO PROMEDIO MEJORES | AH26: DISMINUCION DEL FONDO CON PENSION JUSTA
B27: AÑO | C27: EDAD INI AÑO | D27: CREC. SALARIO | E27: SALARIO MENSUAL | F27: CUOTAS APORTADAS | G27: SALARIO ANUAL | I27: AÑO | J27: EDAD FIN AÑO | K27: INDICADOR | L27: TASA O-P SALARIO | M27: SALARIO ANNUAL CON MAX 2500 MENSUAL | N27: CUENTA INICIAL | O27: APORTES | P27: INTERESES | Q27: CUENTA FINAL | S27: AÑO | T27: EDAD FIN AÑO | U27: INDICADOR | V27: TASA O-P SALARIO | W27: TASA O-P XIII | X27: CUENTA INICIAL | Y27: APORTES | Z27: INTERESES | AA27: CUENTA FINAL | AC27: AÑO | AD27: EDAD | AE27: CUOTAS APORTADAS | AF27: SALARIO COTIZADO PARA PROMEDIO | AH27: AÑO | AI27: EDAD FIN AÑO | AJ27: CUENTA INICIAL | AK27: PENSION ANUAL PAGADA JUSTA | AL27: INTERES | AM27: CUENTA FINAL
AM28: =+X16 -> 228512.05
B29: =+YEAR(B5) -> 1981 | C29: =+B6 -> 19 | D29: 1 | E29: =+IFERROR(G29/F29,0) -> 140 | F29: 3 | G29: 420 | I29: =+B29 -> 1981 | J29: =+C29+1 -> 20 | K29: =+IF(C29<$B$7,1,0) -> 1 | L29: =B11 -> 0.15 | M29: =+IF($B$2=1,IF(G29<=2500*12,G29,2500*12),G29) -> 420 | N29: =+Q28 -> 0 | O29: =+L29*M29*$K29 -> 63 | P29: =+N29*$B$14 -> 0 | Q29: =+(N29+O29+P29) -> 63 | S29: =+I29 -> 1981 | T29: =+J29 -> 20 | U29: =+IF($C29>=$B$7,1,0) -> 0 | V29: =+$B$12*U29 -> 0 | W29: =+U29*$B$13 -> 0 | X29: =+AA28 -> 0 | Y29: =+(G29*V29)*U29 -> 0 | Z29: =+X29*$B$15*U29 -> 0 | AA29: =+(X29+Y29+Z29) -> 0 | AC29: =+B29 -> 1981 | AD29: =+C29 -> 19 | AE29: =+IF(T29<=$X$12,1,0)*F29 -> 3 | AF29: =+IF(T29>$X$12,0,IF($B$2=1,IF($AD29<$B$7,IF(G29<=$B$19*12,G29,$B$19*12),G29),G29)) -> 420 | AH29: 1 | AI29: =+X12 -> 65 | AJ29: =+AM28 -> 228512.05 | AK29: =+X19 -> 14917.242 | AL29: =+(AJ29-AK29)*$B$15 -> 10679.74 | AM29: =+AJ29-AK29+AL29 -> 224274.54
B30: =+B29+1 -> 1982 | C30: =+C29+1 -> 20 | D30: =+D29*(1+$B$10) -> 1.015 | E30: =+IFERROR(G30/F30,0) -> 164.5 | F30: 10 | G30: 1645 | I30: =+B30 -> 1982 | J30: =+C30+1 -> 21 | K30: =+IF(C30<$B$7,1,0) -> 1 | L30: =+L29 -> 0.15 | M30: =+IF($B$2=1,IF(G30<=2500*12,G30,2500*12),G30) -> 1645 | N30: =+Q29 -> 63 | O30: =+L30*M30*$K30 -> 246.75 | P30: =+N30*$B$14 -> 2.52 | Q30: =+(N30+O30+P30) -> 312.27 | S30: =+I30 -> 1982 | T30: =+J30 -> 21 | U30: =+IF($C30>=$B$7,1,0) -> 0 | V30: =+$B$12*U30 -> 0 | W30: =+U30*$B$13 -> 0 | X30: =+AA29 -> 0 | Y30: =+(G30*V30)*U30 -> 0 | Z30: =+X30*$B$15*U30 -> 0 | AA30: =+(X30+Y30+Z30) -> 0 | AC30: =+AC29+1 -> 1982 | AD30: =+C30 -> 20 | AE30: =+IF(T30<=$X$12,1,0)*F30 -> 10 | AF30: =+IF(T30>$X$12,0,IF($B$2=1,IF($AD30<$B$7,IF(G30<=$B$19*12,G30,$B$19*12),G30),G30)) -> 1645 | AH30: =+AH29+1 -> 2 | AI30: =+AI29+1 -> 66 | AJ30: =+AM29 -> 224274.54 | AK30: =+AK29 -> 14917.242 | AL30: =+(AJ30-AK30)*$B$15 -> 10467.865 | AM30: =+AJ30-AK30+AL30 -> 219825.17
B31: =+B30+1 -> 1983 | C31: =+C30+1 -> 21 | D31: =+D30*(1+$B$10) -> 1.030225 | E31: =+IFERROR(G31/F31,0) -> 194.16667 | F31: 12 | G31: 2330 | I31: =+B31 -> 1983 | J31: =+C31+1 -> 22 | K31: =+IF(C31<$B$7,1,0) -> 1 | L31: =+L30 -> 0.15 | M31: =+IF($B$2=1,IF(G31<=2500*12,G31,2500*12),G31) -> 2330 | N31: =+Q30 -> 312.27 | O31: =+L31*M31*$K31 -> 349.5 | P31: =+N31*$B$14 -> 12.4908 | Q31: =+(N31+O31+P31) -> 674.2608 | S31: =+I31 -> 1983 | T31: =+J31 -> 22 | U31: =+IF($C31>=$B$7,1,0) -> 0 | V31: =+$B$12*U31 -> 0 | W31: =+U31*$B$13 -> 0 | X31: =+AA30 -> 0 | Y31: =+(G31*V31)*U31 -> 0 | Z31: =+X31*$B$15*U31 -> 0 | AA31: =+(X31+Y31+Z31) -> 0 | AC31: =+AC30+1 -> 1983 | AD31: =+C31 -> 21 | AE31: =+IF(T31<=$X$12,1,0)*F31 -> 12 | AF31: =+IF(T31>$X$12,0,IF($B$2=1,IF($AD31<$B$7,IF(G31<=$B$19*12,G31,$B$19*12),G31),G31)) -> 2330 | AH31: =+AH30+1 -> 3 | AI31: =+AI30+1 -> 67 | AJ31: =+AM30 -> 219825.17 | AK31: =+AK30 -> 14917.242 | AL31: =+(AJ31-AK31)*$B$15 -> 10245.396 | AM31: =+AJ31-AK31+AL31 -> 215153.32
B32: =+B31+1 -> 1984 | C32: =+C31+1 -> 22 | D32: =+D31*(1+$B$10) -> 1.0456784 | E32: =+IFERROR(G32/F32,0) -> 204.66667 | F32: 12 | G32: 2456 | I32: =+B32 -> 1984 | J32: =+C32+1 -> 23 | K32: =+IF(C32<$B$7,1,0) -> 1 | L32: =+L31 -> 0.15 | M32: =+IF($B$2=1,IF(G32<=2500*12,G32,2500*12),G32) -> 2456 | N32: =+Q31 -> 674.2608 | O32: =+L32*M32*$K32 -> 368.4 | P32: =+N32*$B$14 -> 26.970432 | Q32: =+(N32+O32+P32) -> 1069.6312 | S32: =+I32 -> 1984 | T32: =+J32 -> 23 | U32: =+IF($C32>=$B$7,1,0) -> 0 | V32: =+$B$12*U32 -> 0 | W32: =+U32*$B$13 -> 0 | X32: =+AA31 -> 0 | Y32: =+(G32*V32)*U32 -> 0 | Z32: =+X32*$B$15*U32 -> 0 | AA32: =+(X32+Y32+Z32) -> 0 | AC32: =+AC31+1 -> 1984 | AD32: =+C32 -> 22 | AE32: =+IF(T32<=$X$12,1,0)*F32 -> 12 | AF32: =+IF(T32>$X$12,0,IF($B$2=1,IF($AD32<$B$7,IF(G32<=$B$19*12,G32,$B$19*12),G32),G32)) -> 2456 | AH32: =+AH31+1 -> 4 | AI32: =+AI31+1 -> 68 | AJ32: =+AM31 -> 215153.32 | AK32: =+AK31 -> 14917.242 | AL32: =+(AJ32-AK32)*$B$15 -> 10011.804 | AM32: =+AJ32-AK32+AL32 -> 210247.88
B33: =+B32+1 -> 1985 | C33: =+C32+1 -> 23 | D33: =+D32*(1+$B$10) -> 1.0613636 | E33: =+IFERROR(G33/F33,0) -> 196.33333 | F33: 12 | G33: 2356 | I33: =+B33 -> 1985 | J33: =+C33+1 -> 24 | K33: =+IF(C33<$B$7,1,0) -> 1 | L33: =+L32 -> 0.15 | M33: =+IF($B$2=1,IF(G33<=2500*12,G33,2500*12),G33) -> 2356 | N33: =+Q32 -> 1069.6312 | O33: =+L33*M33*$K33 -> 353.4 | P33: =+N33*$B$14 -> 42.785249 | Q33: =+(N33+O33+P33) -> 1465.8165 | S33: =+I33 -> 1985 | T33: =+J33 -> 24 | U33: =+IF($C33>=$B$7,1,0) -> 0 | V33: =+$B$12*U33 -> 0 | W33: =+U33*$B$13 -> 0 | X33: =+AA32 -> 0 | Y33: =+(G33*V33)*U33 -> 0 | Z33: =+X33*$B$15*U33 -> 0 | AA33: =+(X33+Y33+Z33) -> 0 | AC33: =+AC32+1 -> 1985 | AD33: =+C33 -> 23 | AE33: =+IF(T33<=$X$12,1,0)*F33 -> 12 | AF33: =+IF(T33>$X$12,0,IF($B$2=1,IF($AD33<$B$7,IF(G33<=$B$19*12,G33,$B$19*12),G33),G33)) -> 2356 | AH33: =+AH32+1 -> 5 | AI33: =+AI32+1 -> 69 | AJ33: =+AM32 -> 210247.88 | AK33: =+AK32 -> 14917.242 | AL33: =+(AJ33-AK33)*$B$15 -> 9766.5321 | AM33: =+AJ33-AK33+AL33 -> 205097.17
B34: =+B33+1 -> 1986 | C34: =+C33+1 -> 24 | D34: =+D33*(1+$B$10) -> 1.077284 | E34: =+IFERROR(G34/F34,0) -> 206.08333 | F34: 12 | G34: 2473 | I34: =+B34 -> 1986 | J34: =+C34+1 -> 25 | K34: =+IF(C34<$B$7,1,0) -> 1 | L34: =+L33 -> 0.15 | M34: =+IF($B$2=1,IF(G34<=2500*12,G34,2500*12),G34) -> 2473 | N34: =+Q33 -> 1465.8165 | O34: =+L34*M34*$K34 -> 370.95 | P34: =+N34*$B$14 -> 58.632659 | Q34: =+(N34+O34+P34) -> 1895.3991 | S34: =+I34 -> 1986 | T34: =+J34 -> 25 | U34: =+IF($C34>=$B$7,1,0) -> 0 | V34: =+$B$12*U34 -> 0 | W34: =+U34*$B$13 -> 0 | X34: =+AA33 -> 0 | Y34: =+(G34*V34)*U34 -> 0 | Z34: =+X34*$B$15*U34 -> 0 | AA34: =+(X34+Y34+Z34) -> 0 | AC34: =+AC33+1 -> 1986 | AD34: =+C34 -> 24 | AE34: =+IF(T34<=$X$12,1,0)*F34 -> 12 | AF34: =+IF(T34>$X$12,0,IF($B$2=1,IF($AD34<$B$7,IF(G34<=$B$19*12,G34,$B$19*12),G34),G34)) -> 2473 | AH34: =+AH33+1 -> 6 | AI34: =+AI33+1 -> 70 | AJ34: =+AM33 -> 205097.17 | AK34: =+AK33 -> 14917.242 | AL34: =+(AJ34-AK34)*$B$15 -> 9508.9966 | AM34: =+AJ34-AK34+AL34 -> 199688.93
B35: =+B34+1 -> 1987 | C35: =+C34+1 -> 25 | D35: =+D34*(1+$B$10) -> 1.0934433 | E35: =+IFERROR(G35/F35,0) -> 276.66667 | F35: 12 | G35: 3320 | I35: =+B35 -> 1987 | J35: =+C35+1 -> 26 | K35: =+IF(C35<$B$7,1,0) -> 1 | L35: =+L34 -> 0.15 | M35: =+IF($B$2=1,IF(G35<=2500*12,G35,2500*12),G35) -> 3320 | N35: =+Q34 -> 1895.3991 | O35: =+L35*M35*$K35 -> 498 | P35: =+N35*$B$14 -> 75.815966 | Q35: =+(N35+O35+P35) -> 2469.2151 | S35: =+I35 -> 1987 | T35: =+J35 -> 26 | U35: =+IF($C35>=$B$7,1,0) -> 0 | V35: =+$B$12*U35 -> 0 | W35: =+U35*$B$13 -> 0 | X35: =+AA34 -> 0 | Y35: =+(G35*V35)*U35 -> 0 | Z35: =+X35*$B$15*U35 -> 0 | AA35: =+(X35+Y35+Z35) -> 0 | AC35: =+AC34+1 -> 1987 | AD35: =+C35 -> 25 | AE35: =+IF(T35<=$X$12,1,0)*F35 -> 12 | AF35: =+IF(T35>$X$12,0,IF($B$2=1,IF($AD35<$B$7,IF(G35<=$B$19*12,G35,$B$19*12),G35),G35)) -> 3320 | AH35: =+AH34+1 -> 7 | AI35: =+AI34+1 -> 71 | AJ35: =+AM34 -> 199688.93 | AK35: =+AK34 -> 14917.242 | AL35: =+(AJ35-AK35)*$B$15 -> 9238.5844 | AM35: =+AJ35-AK35+AL35 -> 194010.27
B36: =+B35+1 -> 1988 | C36: =+C35+1 -> 26 | D36: =+D35*(1+$B$10) -> 1.1098449 | E36: =+IFERROR(G36/F36,0) -> 300.25 | F36: 12 | G36: 3603 | I36: =+B36 -> 1988 | J36: =+C36+1 -> 27 | K36: =+IF(C36<$B$7,1,0) -> 1 | L36: =+L35 -> 0.15 | M36: =+IF($B$2=1,IF(G36<=2500*12,G36,2500*12),G36) -> 3603 | N36: =+Q35 -> 2469.2151 | O36: =+L36*M36*$K36 -> 540.45 | P36: =+N36*$B$14 -> 98.768604 | Q36: =+(N36+O36+P36) -> 3108.4337 | S36: =+I36 -> 1988 | T36: =+J36 -> 27 | U36: =+IF($C36>=$B$7,1,0) -> 0 | V36: =+$B$12*U36 -> 0 | W36: =+U36*$B$13 -> 0 | X36: =+AA35 -> 0 | Y36: =+(G36*V36)*U36 -> 0 | Z36: =+X36*$B$15*U36 -> 0 | AA36: =+(X36+Y36+Z36) -> 0 | AC36: =+AC35+1 -> 1988 | AD36: =+C36 -> 26 | AE36: =+IF(T36<=$X$12,1,0)*F36 -> 12 | AF36: =+IF(T36>$X$12,0,IF($B$2=1,IF($AD36<$B$7,IF(G36<=$B$19*12,G36,$B$19*12),G36),G36)) -> 3603 | AH36: =+AH35+1 -> 8 | AI36: =+AI35+1 -> 72 | AJ36: =+AM35 -> 194010.27 | AK36: =+AK35 -> 14917.242 | AL36: =+(AJ36-AK36)*$B$15 -> 8954.6515 | AM36: =+AJ36-AK36+AL36 -> 188047.68
B37: =+B36+1 -> 1989 | C37: =+C36+1 -> 27 | D37: =+D36*(1+$B$10) -> 1.1264926 | E37: =+IFERROR(G37/F37,0) -> 300.25 | F37: 12 | G37: 3603 | I37: =+B37 -> 1989 | J37: =+C37+1 -> 28 | K37: =+IF(C37<$B$7,1,0) -> 1 | L37: =+L36 -> 0.15 | M37: =+IF($B$2=1,IF(G37<=2500*12,G37,2500*12),G37) -> 3603 | N37: =+Q36 -> 3108.4337 | O37: =+L37*M37*$K37 -> 540.45 | P37: =+N37*$B$14 -> 124.33735 | Q37: =+(N37+O37+P37) -> 3773.2211 | S37: =+I37 -> 1989 | T37: =+J37 -> 28 | U37: =+IF($C37>=$B$7,1,0) -> 0 | V37: =+$B$12*U37 -> 0 | W37: =+U37*$B$13 -> 0 | X37: =+AA36 -> 0 | Y37: =+(G37*V37)*U37 -> 0 | Z37: =+X37*$B$15*U37 -> 0 | AA37: =+(X37+Y37+Z37) -> 0 | AC37: =+AC36+1 -> 1989 | AD37: =+C37 -> 27 | AE37: =+IF(T37<=$X$12,1,0)*F37 -> 12 | AF37: =+IF(T37>$X$12,0,IF($B$2=1,IF($AD37<$B$7,IF(G37<=$B$19*12,G37,$B$19*12),G37),G37)) -> 3603 | AH37: =+AH36+1 -> 9 | AI37: =+AI36+1 -> 73 | AJ37: =+AM36 -> 188047.68 | AK37: =+AK36 -> 14917.242 | AL37: =+(AJ37-AK37)*$B$15 -> 8656.522 | AM37: =+AJ37-AK37+AL37 -> 181786.96
B38: =+B37+1 -> 1990 | C38: =+C37+1 -> 28 | D38: =+D37*(1+$B$10) -> 1.14339 | E38: =+IFERROR(G38/F38,0) -> 302.75 | F38: 12 | G38: 3633 | I38: =+B38 -> 1990 | J38: =+C38+1 -> 29 | K38: =+IF(C38<$B$7,1,0) -> 1 | L38: =+L37 -> 0.15 | M38: =+IF($B$2=1,IF(G38<=2500*12,G38,2500*12),G38) -> 3633 | N38: =+Q37 -> 3773.2211 | O38: =+L38*M38*$K38 -> 544.95 | P38: =+N38*$B$14 -> 150.92884 | Q38: =+(N38+O38+P38) -> 4469.0999 | S38: =+I38 -> 1990 | T38: =+J38 -> 29 | U38: =+IF($C38>=$B$7,1,0) -> 0 | V38: =+$B$12*U38 -> 0 | W38: =+U38*$B$13 -> 0 | X38: =+AA37 -> 0 | Y38: =+(G38*V38)*U38 -> 0 | Z38: =+X38*$B$15*U38 -> 0 | AA38: =+(X38+Y38+Z38) -> 0 | AC38: =+AC37+1 -> 1990 | AD38: =+C38 -> 28 | AE38: =+IF(T38<=$X$12,1,0)*F38 -> 12 | AF38: =+IF(T38>$X$12,0,IF($B$2=1,IF($AD38<$B$7,IF(G38<=$B$19*12,G38,$B$19*12),G38),G38)) -> 3633 | AH38: =+AH37+1 -> 10 | AI38: =+AI37+1 -> 74 | AJ38: =+AM37 -> 181786.96 | AK38: =+AK37 -> 14917.242 | AL38: =+(AJ38-AK38)*$B$15 -> 8343.486 | AM38: =+AJ38-AK38+AL38 -> 175213.21
B39: =+B38+1 -> 1991 | C39: =+C38+1 -> 29 | D39: =+D38*(1+$B$10) -> 1.1605408 | E39: =+IFERROR(G39/F39,0) -> 330.25 | F39: 12 | G39: 3963 | I39: =+B39 -> 1991 | J39: =+C39+1 -> 30 | K39: =+IF(C39<$B$7,1,0) -> 1 | L39: =+L38 -> 0.15 | M39: =+IF($B$2=1,IF(G39<=2500*12,G39,2500*12),G39) -> 3963 | N39: =+Q38 -> 4469.0999 | O39: =+L39*M39*$K39 -> 594.45 | P39: =+N39*$B$14 -> 178.764 | Q39: =+(N39+O39+P39) -> 5242.3139 | S39: =+I39 -> 1991 | T39: =+J39 -> 30 | U39: =+IF($C39>=$B$7,1,0) -> 0 | V39: =+$B$12*U39 -> 0 | W39: =+U39*$B$13 -> 0 | X39: =+AA38 -> 0 | Y39: =+(G39*V39)*U39 -> 0 | Z39: =+X39*$B$15*U39 -> 0 | AA39: =+(X39+Y39+Z39) -> 0 | AC39: =+AC38+1 -> 1991 | AD39: =+C39 -> 29 | AE39: =+IF(T39<=$X$12,1,0)*F39 -> 12 | AF39: =+IF(T39>$X$12,0,IF($B$2=1,IF($AD39<$B$7,IF(G39<=$B$19*12,G39,$B$19*12),G39),G39)) -> 3963 | AH39: =+AH38+1 -> 11 | AI39: =+AI38+1 -> 75 | AJ39: =+AM38 -> 175213.21 | AK39: =+AK38 -> 14917.242 | AL39: =+(AJ39-AK39)*$B$15 -> 8014.7982 | AM39: =+AJ39-AK39+AL39 -> 168310.76
B40: =+B39+1 -> 1992 | C40: =+C39+1 -> 30 | D40: =+D39*(1+$B$10) -> 1.1779489 | E40: =+IFERROR(G40/F40,0) -> 371.75 | F40: 12 | G40: 4461 | I40: =+B40 -> 1992 | J40: =+C40+1 -> 31 | K40: =+IF(C40<$B$7,1,0) -> 1 | L40: =+L39 -> 0.15 | M40: =+IF($B$2=1,IF(G40<=2500*12,G40,2500*12),G40) -> 4461 | N40: =+Q39 -> 5242.3139 | O40: =+L40*M40*$K40 -> 669.15 | P40: =+N40*$B$14 -> 209.69256 | Q40: =+(N40+O40+P40) -> 6121.1565 | S40: =+I40 -> 1992 | T40: =+J40 -> 31 | U40: =+IF($C40>=$B$7,1,0) -> 0 | V40: =+$B$12*U40 -> 0 | W40: =+U40*$B$13 -> 0 | X40: =+AA39 -> 0 | Y40: =+(G40*V40)*U40 -> 0 | Z40: =+X40*$B$15*U40 -> 0 | AA40: =+(X40+Y40+Z40) -> 0 | AC40: =+AC39+1 -> 1992 | AD40: =+C40 -> 30 | AE40: =+IF(T40<=$X$12,1,0)*F40 -> 12 | AF40: =+IF(T40>$X$12,0,IF($B$2=1,IF($AD40<$B$7,IF(G40<=$B$19*12,G40,$B$19*12),G40),G40)) -> 4461 | AH40: =+AH39+1 -> 12 | AI40: =+AI39+1 -> 76 | AJ40: =+AM39 -> 168310.76 | AK40: =+AK39 -> 14917.242 | AL40: =+(AJ40-AK40)*$B$15 -> 7669.676 | AM40: =+AJ40-AK40+AL40 -> 161063.2
B41: =+B40+1 -> 1993 | C41: =+C40+1 -> 31 | D41: =+D40*(1+$B$10) -> 1.1956182 | E41: =+IFERROR(G41/F41,0) -> 512.5 | F41: 12 | G41: 6150 | I41: =+B41 -> 1993 | J41: =+C41+1 -> 32 | K41: =+IF(C41<$B$7,1,0) -> 1 | L41: =+L40 -> 0.15 | M41: =+IF($B$2=1,IF(G41<=2500*12,G41,2500*12),G41) -> 6150 | N41: =+Q40 -> 6121.1565 | O41: =+L41*M41*$K41 -> 922.5 | P41: =+N41*$B$14 -> 244.84626 | Q41: =+(N41+O41+P41) -> 7288.5027 | S41: =+I41 -> 1993 | T41: =+J41 -> 32 | U41: =+IF($C41>=$B$7,1,0) -> 0 | V41: =+$B$12*U41 -> 0 | W41: =+U41*$B$13 -> 0 | X41: =+AA40 -> 0 | Y41: =+(G41*V41)*U41 -> 0 | Z41: =+X41*$B$15*U41 -> 0 | AA41: =+(X41+Y41+Z41) -> 0 | AC41: =+AC40+1 -> 1993 | AD41: =+C41 -> 31 | AE41: =+IF(T41<=$X$12,1,0)*F41 -> 12 | AF41: =+IF(T41>$X$12,0,IF($B$2=1,IF($AD41<$B$7,IF(G41<=$B$19*12,G41,$B$19*12),G41),G41)) -> 6150 | AH41: =+AH40+1 -> 13 | AI41: =+AI40+1 -> 77 | AJ41: =+AM40 -> 161063.2 | AK41: =+AK40 -> 14917.242 | AL41: =+(AJ41-AK41)*$B$15 -> 7307.2977 | AM41: =+AJ41-AK41+AL41 -> 153453.25
... B53: =+B52+1 -> 2005 | C53: =+C52+1 -> 43 | D53: =+D52*(1+$B$10) -> 1.4295028 | E53: =+IFERROR(G53/F53,0) -> 1637.5 | F53: 12 | G53: 19650 | I53: =+B53 -> 2005 | J53: =+C53+1 -> 44 | K53: =+IF(C53<$B$7,1,0) -> 1 | L53: =+L52 -> 0.15 | M53: =+IF($B$2=1,IF(G53<=2500*12,G53,2500*12),G53) -> 19650 | N53: =+Q52 -> 35312.775 | O53: =+L53*M53*$K53 -> 2947.5 | P53: =+N53*$B$14 -> 1412.511 | Q53: =+(N53+O53+P53) -> 39672.786 | S53: =+I53 -> 2005 | T53: =+J53 -> 44 | U53: =+IF($C53>=$B$7,1,0) -> 0 | V53: =+$B$12*U53 -> 0 | W53: =+U53*$B$13 -> 0 | X53: =+AA52 -> 0 | Y53: =+(G53*V53)*U53 -> 0 | Z53: =+X53*$B$15*U53 -> 0 | AA53: =+(X53+Y53+Z53) -> 0 | AC53: =+AC52+1 -> 2005 | AD53: =+C53 -> 43 | AE53: =+IF(T53<=$X$12,1,0)*F53 -> 12 | AF53: =+IF(T53>$X$12,0,IF($B$2=1,IF($AD53<$B$7,IF(G53<=$B$19*12,G53,$B$19*12),G53),G53)) -> 19650 | AH53: =+AH52+1 -> 25 | AI53: =+AI52+1 -> 89 | AJ53: =+AM52 -> 39934.753 | AK53: =+AK52 -> 14917.242 | AL53: =+(AJ53-AK53)*$B$15 -> 1250.8756 | AM53: =+AJ53-AK53+AL53 -> 26268.387
...

Sheet salidaformulas
A2: SEXO | B2: M
A3: EDAD ENTRADA | B3: 22 | E3: TIPO DE SISTEMA | F3: COMPONENTE 1 | G3: COMPONENTE 2 | H3: personas aprox
A4: EDAD DE JUBILACION | B4: 62 | E4: SISTEMA DE BENEFICIO DEFINIDO | F4: COMPONENTE SOLIDARIO | H4: 600K | I4: SOLIDARIO> EL BENEFICIO SE CALCULA CON UNA FORMULA SENCILLA, PERO QUE PUEDE HACER QUE EL SISTEMA QUIEBRE SINO HAY SUSTENTO PARA EL FINANCIAMIENTO
A5: AÑOS EN SISTEMA | B5: =+B4-B3 -> 40 | E5: SISTEMA MIXTO | F5: COMPONENTE SOLIDARIO | G5: AHORRO | H5: 600K | I5: AHORRO> EL BENEFICIO SE CALCULA CONFORME A LO QUE ESTA ACUMULADO EN LA CUENTA DE AHORRO
A6: INTERES | B6: 0.04 | E6: SISTEMA CUENTA INDIVIDUAL | G6: AHORRO
A7: FACTOR PENSIONAMIENTO MANCOMUNADO | B7: 5.1543312
A9: A SALARIO MENSUAL | B9: B CUOTAS PROMEDIO PAGADAS POR AÑO | C9: C AÑOS EN EL SISTEMA | D9: D CUOTAS TOTALES PAGADAS =B*C | E9: E AÑOS DE TRABAJO FORMALES | F9: F SALARIO ANNUAL =B*A | G9: G SALARIO PRIMER PILAR o SOLIDARIO =$500*B | H9: H SALARIO SEGUNDO PILAR o COMP AHORRO =F-G | I9: I CUOTA ANUAL TOTAL =15%*F | J9: J CUOTA ANUAL CUENTA INDIVIDUAL 2do Pilar Ahorro =10%*H | K9: K PROMEDIO ANUAL MEJORES 10 AÑOS TOTAL | L9: L PROMEDIO ANUAL MEJORES 10 AÑOS 1er PILAR | M9: M PENSION MENSUAL COMPONENTE BD 1ER PILAR =(60%*L+ (1.25%*(E-20)*L))/12 | N9: N CUENTA INDIVIDUAL ACUMULADA 2DO PILAR SMIXTO Ley 51 al 4% A EDAD JUBILACION. Ver Nota** | O9: O PENSION COMPONENTE AHORRO 2do PILAR =(N/1000)*factor Pensionamiento | P9: P CUENTA INDIVIDUAL ACUMULADA TOTAL NUEVA LEY 462 al 4% A EDAD DE JUBILACION. VER NOTA ** | Q9: Q JUBILACIÓN P NUEVA LEY 462 =(P/1000)*factor Pensionamiento | R9: R JUBILACION SEGUN LEY 51 SISTEMA MIXTO =M+O | S9: S JUBILACIÓN LEY 51 SEBD =(60%*K+ (1.25%*(E-20)*K))/12 | T9: T TASA DE REEMPLAZO NUEVA LEY=Q/K | U9: U TASAS DE REEMPLAZO Ley 51 Mixto=R/K | V9: V TASAS DE REEMPLAZO Ley 51 SEBD=S/K | W9: AÑOS EN EL SISTEMA | X9: AÑOS DE TRABAJO FORMALES
A10: 700 | B10: 6 | C10: =+B5 -> 40 | D10: =+B10*C10 -> 240 | E10: =+D10/12 -> 20 | F10: =+B10*A10 -> 4200 | G10: =+IF(A10>500,500*B10,A10*B10) -> 3000 | H10: =+F10-G10 -> 1200 | I10: =0.15*F10 -> 630 | J10: =+H10*0.1 -> 120 | K10: =+F10 -> 4200 | L10: =+G10 -> 3000 | M10: =(60%*G10+1.25%*(E10-20)*G10)/12 -> 150 | N10: =+(((1+$B$6)^C10-1)/$B$6)*J10 -> 11403.062 | O10: =+N10*0.001*$B$7 -> 58.775157 | P10: =+(((1+$B$6)^C10-1)/$B$6)*I10 -> 59866.075 | Q10: =+P10*0.001*$B$7 -> 308.56958 | R10: =+O10+M10 -> 208.77516 | S10: =(60%*F10+1.25%*(E10-20)*F10)/12 -> 210 | T10: =+IFERROR((Q10*12)/$K10,0) -> 0.88162736 | U10: =+IFERROR((R10*12)/$K10,0) -> 0.59650045 | V10: =+IFERROR(S10*12/K10,0) -> 0.6 | W10: =+C10 -> 40 | X10: =+E10 -> 20
A11: =+A10 -> 700 | B11: 7.5 | C11: =+C10 -> 40 | D11: =+B11*C11 -> 300 | E11: =+D11/12 -> 25 | F11: =+B11*A11 -> 5250 | G11: =+IF(A11>500,500*B11,A11*B11) -> 3750 | H11: =+F11-G11 -> 1500 | I11: =0.15*F11 -> 787.5 | J11: =+H11*0.1 -> 150 | K11: =+F11 -> 5250 | L11: =+G11 -> 3750 | M11: =(60%*G11+1.25%*(E11-20)*G11)/12 -> 207.03125 | N11: =+(((1+$B$6)^C11-1)/$B$6)*J11 -> 14253.827 | O11: =+N11*0.001*$B$7 -> 73.468947 | P11: =+(((1+$B$6)^C11-1)/$B$6)*I11 -> 74832.594 | Q11: =+P11*0.001*$B$7 -> 385.71197 | R11: =+O11+M11 -> 280.5002 | S11: =(60%*F11+1.25%*(E11-20)*F11)/12 -> 289.84375 | T11: =+IFERROR((Q11*12)/$K11,0) -> 0.88162736 | U11: =+IFERROR((R11*12)/$K11,0) -> 0.64114331 | V11: =+IFERROR(S11*12/K11,0) -> 0.6625 | W11: =+C11 -> 40 | X11: =+E11 -> 25
A12: =+A11 -> 700 | B12: 9 | C12: =+C11 -> 40 | D12: =+B12*C12 -> 360 | E12: =+D12/12 -> 30 | F12: =+B12*A12 -> 6300 | G12: =+IF(A12>500,500*B12,A12*B12) -> 4500 | H12: =+F12-G12 -> 1800 | I12: =0.15*F12 -> 945 | J12: =+H12*0.1 -> 180 | K12: =+F12 -> 6300 | L12: =+G12 -> 4500 | M12: =(60%*G12+1.25%*(E12-20)*G12)/12 -> 271.875 | N12: =+(((1+$B$6)^C12-1)/$B$6)*J12 -> 17104.593 | O12: =+N12*0.001*$B$7 -> 88.162736 | P12: =+(((1+$B$6)^C12-1)/$B$6)*I12 -> 89799.112 | Q12: =+P12*0.001*$B$7 -> 462.85437 | R12: =+O12+M12 -> 360.03774 | S12: =(60%*F12+1.25%*(E12-20)*F12)/12 -> 380.625 | T12: =+IFERROR((Q12*12)/$K12,0) -> 0.88162736 | U12: =+IFERROR((R12*12)/$K12,0) -> 0.68578616 | V12: =+IFERROR(S12*12/K12,0) -> 0.725 | W12: =+C12 -> 40 | X12: =+E12 -> 30
A13: =+A12 -> 700 | B13: 10.5 | C13: =+C12 -> 40 | D13: =+B13*C13 -> 420 | E13: =+D13/12 -> 35 | F13: =+B13*A13 -> 7350 | G13: =+IF(A13>500,500*B13,A13*B13) -> 5250 | H13: =+F13-G13 -> 2100 | I13: =0.15*F13 -> 1102.5 | J13: =+H13*0.1 -> 210 | K13: =+F13 -> 7350 | L13: =+G13 -> 5250 | M13: =(60%*G13+1.25%*(E13-20)*G13)/12 -> 344.53125 | N13: =+(((1+$B$6)^C13-1)/$B$6)*J13 -> 19955.358 | O13: =+N13*0.001*$B$7 -> 102.85653 | P13: =+(((1+$B$6)^C13-1)/$B$6)*I13 -> 104765.63 | Q13: =+P13*0.001*$B$7 -> 539.99676 | R13: =+O13+M13 -> 447.38778 | S13: =(60%*F13+1.25%*(E13-20)*F13)/12 -> 482.34375 | T13: =+IFERROR((Q13*12)/$K13,0) -> 0.88162736 | U13: =+IFERROR((R13*12)/$K13,0) -> 0.73042902 | V13: =+IFERROR(S13*12/K13,0) -> 0.7875 | W13: =+C13 -> 40 | X13: =+E13 -> 35
A14: =+A13 -> 700 | B14: 12 | C14: =+C13 -> 40 | D14: =+B14*C14 -> 480 | E14: =+D14/12 -> 40 | F14: =+B14*A14 -> 8400 | G14: =+IF(A14>500,500*B14,A14*B14) -> 6000 | H14: =+F14-G14 -> 2400 | I14: =0.15*F14 -> 1260 | J14: =+H14*0.1 -> 240 | K14: =+F14 -> 8400 | L14: =+G14 -> 6000 | M14: =(60%*G14+1.25%*(E14-20)*G14)/12 -> 425 | N14: =+(((1+$B$6)^C14-1)/$B$6)*J14 -> 22806.124 | O14: =+N14*0.001*$B$7 -> 117.55031 | P14: =+(((1+$B$6)^C14-1)/$B$6)*I14 -> 119732.15 | Q14: =+P14*0.001*$B$7 -> 617.13915 | R14: =+O14+M14 -> 542.55031 | S14: =(60%*F14+1.25%*(E14-20)*F14)/12 -> 595 | T14: =+IFERROR((Q14*12)/$K14,0) -> 0.88162736 | U14: =+IFERROR((R14*12)/$K14,0) -> 0.77507188 | V14: =+IFERROR(S14*12/K14,0) -> 0.85 | W14: =+C14 -> 40 | X14: =+E14 -> 40
A17: Nota>**

Sheet calculo 20
B1: DATOS BASICOS | BH1: BENEFICIO DE JUBILACION CSS SEBD
B2: SISTEMA | F2: 1 | BH2: CUOTAS APORTADAS | BM2: =+SUM(K28:K76) -> 240
B3: SEXO | F3: =+salidaformulas!B2 -> M | Q3: MIXTO | AA3: CAPITALIZACIÓN SOLIDARIA | BH3: CUOTAS EN EXCESO A DENSIDAD MIN | BM3: =+IF(BM2>240,BM2-F13,0) -> 0
B4: EDAD ENTRADA | F4: =+salidaformulas!B3 -> 22 | I4: SOLIDARIO | BH4: TASA DE REEMPLAZO AJUSTADA SEBD LEY 51 | BM4: =IF(F7<=7,BN4,BN4*AF13) -> 0.6 | BN4: =IF(AND(BM2>=180,BM2<240),($F$14+INT(BM3/12)*$F$15)*BM2/240,IF(BM2<180,0,($F$14+INT(BM3/12)*$F$15))) -> 0.6
B5: EDAD ACTUAL DIA DE REFORMA | F5: =+F4 -> 22 | J5: Mej. Salario Anual | K5: Mej Salario Anual | S5: Mej. Salario Anual | T5: Mej Salario Anual | BH5: PENSION ANNUAL A RECIBIR | BM5: =+BM6*12 -> 3180
B6: EDAD DE JUBILACION | F6: =+salidaformulas!B4 -> 62 | I6: Mejores Años | J6: TOTAL | K6: Primer Pilar | R6: Mejores Años | S6: TOTAL | T6: Primer Pilar | BH6: PENSION MENSUAL A RECIBIR | BM6: =IF(BM2>=240,MAX(MAX(BL8:BL10),265),MAX(BL8:BL10)) -> 265
B7: AÑOS PARA JUBILARSE | F7: =+F6-F5 -> 40 | I7: 1 | J7: =LARGE($G$28:$G$65,I7) -> 4200 | K7: =LARGE($L$28:$L$65,I7) -> 3000 | R7: 1 | S7: =+J7 -> 4200 | T7: =+K7 -> 3000 | BL7: PENSION | BM7: PROM. ANUAL | BN7: PROM.MENSUAL
B8: % CUOTA APLICADO ANTES VIGENCIA NVA LEY | F8: 0.15 | I8: 2 | J8: =LARGE($G$28:$G$65,I8) -> 4200 | K8: =LARGE($L$28:$L$65,I8) -> 3000 | R8: 2 | S8: =+J8 -> 4200 | T8: =+K8 -> 3000 | BH8: CALCULO DE LOS MEJORES 10 AÑOS | BL8: =+IF($BM$4*BM8/12>1500,1500,$BM$4*BM8/12) -> 210 | BM8: {=+AVERAGE(LARGE($G$28:$G$76,ROW(INDIRECT("1:10"))))} -> 4200
B9: % CUOTA EMPLEADO EMPLEADOR NUEVA LEY | F9: 0.135 | I9: 3 | J9: =LARGE($G$28:$G$65,I9) -> 4200 | K9: =LARGE($L$28:$L$65,I9) -> 3000 | R9: 3 | S9: =+J9 -> 4200 | T9: =+K9 -> 3000 | BH9: CALCULO DE LOS MEJORES 15 AÑOS (300 CUOTAS Y PROM>=$2,000) | BL9: =+IF($BM$4*BM9/12>2000,2000,$BM$4*BM9/12) -> 0 | BM9: {=IF(AND(BM2>300,AVERAGE(LARGE($G$28:$G$76,ROW(INDIRECT("1:15"))))>=24000),AVERAGE(LARGE($G$28:$G$76,ROW(INDIRECT("1:15")))),0)} -> 0
B10: % XIII EMPLEADO EMPLEADOR NUEVA LEY | F10: 0.18 | I10: 4 | J10: =LARGE($G$28:$G$65,I10) -> 4200 | K10: =LARGE($L$28:$L$65,I10) -> 3000 | R10: 4 | S10: =+J10 -> 4200 | T10: =+K10 -> 3000 | AA10: SCGS-CUANDO VIENE DEL SEBD o SM | BH10: CALCULO DE LOS MEJORES 20 AÑOS (360 cuotas y prom>=$2,500) | BL10: =+IF($BM$4*BM10/12>2500,2500,$BM$4*BM10/12) -> 0 | BM10: {=IF(AND(BM2>360,AVERAGE(LARGE($G$28:$G$76,ROW(INDIRECT("1:20"))))>=30000),AVERAGE(LARGE($G$28:$G$76,ROW(INDIRECT("1:20")))),0)} -> 0
B11: TASA DE RETORNO INVERSIONES ANTES VIG LEY | F11: 0.04 | I11: 5 | J11: =LARGE($G$28:$G$65,I11) -> 4200 | K11: =LARGE($L$28:$L$65,I11) -> 3000 | R11: 5 | S11: =+J11 -> 4200 | T11: =+K11 -> 3000 | AA11: EDAD JUBILACION | AF11: =+F6 -> 62 | AK11: RESULTADO COMPARATIVO | AO11: MONTO | AP11: REEMPLAZO MEJ.AÑOS | BH11: TASA DE REEMPLAZO FINAL DE ESTE CALCULO | BM11: =+BM5/VLOOKUP(MAX(BL8:BL10),BL8:BM10,2,0) -> 0.75714286
B12: TASA RETORNO INVERSIONES PROMEDIO | F12: 0.04 | I12: 6 | J12: =LARGE($G$28:$G$65,I12) -> 4200 | K12: =LARGE($L$28:$L$65,I12) -> 3000 | R12: 6 | S12: =+J12 -> 4200 | T12: =+K12 -> 3000 | AA12: FONDO AHORRADO COP ANTES VIGENCIA NVA LEY | AF12: =+VLOOKUP(AF11,$AB$28:$AI$76,8,FALSE) -> 0 | AG12: R | AK12: PENSION A RECIBIR DEL SEBD | AO12: =+L18 -> 210 | AP12: =+AO12/(J16/12) -> 0.6
A13: A | B13: DENSIDAD MINIMA DE CUOTAS LEY 51 | F13: 240 | I13: 7 | J13: =LARGE($G$28:$G$65,I13) -> 4200 | K13: =LARGE($L$28:$L$65,I13) -> 3000 | R13: 7 | S13: =+J13 -> 4200 | T13: =+K13 -> 3000 | W13: VP | X13: RA*ax | AA13: FACTOR DESCUENTO | AF13: =+IF(AND($B$20=1,$F$2<>1),100%,IF($F$3="M",VLOOKUP(AF11,descuento!$A$6:$B$32,2,FALSE),VLOOKUP(AF11,descuento!$C$6:$D$32,2,FALSE))) -> 1 | AK13: PENSION A RECIBIR SISTEMA MIXTO | AO13: =+U22 -> 208.77516 | AP13: =+AO13/(S17/12) -> 0.59650045 | AV13: FONDO TOTAL APLICABLE | BB13: =+VLOOKUP(AF11,$AW$28:$BE$76,9,FALSE) -> 59866.075 | BH13: BENEFICIO DEL SISTEMA MIXTO
A14: B | B14: TASA DE REEMPLAZO INICIAL LEY 51 | F14: 0.6 | I14: 8 | J14: =LARGE($G$28:$G$65,I14) -> 4200 | K14: =LARGE($L$28:$L$65,I14) -> 3000 | R14: 8 | S14: =+J14 -> 4200 | T14: =+K14 -> 3000 | W14: VP/ax | X14: 12*RM | AA14: FONDO AHORRADO COP DESPUES VIGENCIA NVA LEY | AF14: =+VLOOKUP(AF11,$AL$28:$AT$76,9,FALSE) -> 59866.075 | AG14: S | AK14: PENSION A RECIBIR DEL SCGS | AO14: =+AF17 -> 308.56958 | AP14: =+AO14/(S16/12) -> 0.88162736 | AV14: FACTOR PENSION X MIL | BB14: =+AF16 -> 5.1543312
A15: C | B15: TASA DE REEMPLAZO ADICIONAL LEY 51 | F15: 0.0125 | I15: 9 | J15: =LARGE($G$28:$G$65,I15) -> 4200 | K15: =LARGE($L$28:$L$65,I15) -> 3000 | R15: 9 | S15: =+J15 -> 4200 | T15: =+K15 -> 3000 | W15: vp * (1/ax) | AA15: FONDO TOTAL APLICABLE | AF15: =+AF14+AF12*AF13 -> 59866.075 | AG15: T=R+S | AK15: PENSION A RECIBIR SI ENTRA NUEVO | AO15: =+BB15 -> 308.56958 | AP15: =+AO15/(S17/12) -> 0.88162736 | AV15: PENSION SCGS MENSUAL | BB15: =+BB13*0.001*BB14 -> 308.56958 | BH15: PROMEDIO ANUAL MEJORES 10 AÑOS PRIMER PILAR | BM15: {=+AVERAGE(LARGE($L$28:$L$76,ROW(INDIRECT("1:10"))))} -> 3000
B16: SALMAX MENSUAL COTIZADO ANTES VIG NVA LEY | F16: 2500 | I16: 10 | J16: =LARGE($G$28:$G$65,I16) -> 4200 | K16: =LARGE($L$28:$L$65,I16) -> 3000 | R16: 10 | S16: =+J16 -> 4200 | T16: =+K16 -> 3000 | AA16: FACTOR PENSION X MIL | AF16: =+VLOOKUP(AF11,'bases renta'!$K$20:$L$65,2,FALSE) -> 5.1543312 | AG16: U | AV16: REEMPLAZO MEJ.AÑOS | BB16: =+BB15/(J17/12) -> 0.88162736 | BH16: PENSION MENSUAL A RECIBIR PRIMER PILAR | BM16: =+BM15*BM4/12 -> 150
B17: PORCENTAJE DE CUOTA OP DESCONTADA SMP | F17: 0.035 | H17: F | I17: PROMEDIO ANUAL | J17: =+AVERAGE(J7:J16) -> 4200 | K17: =+AVERAGE(K7:K16) -> 3000 | Q17: F | R17: PROMEDIO ANUAL | S17: =+J17 -> 4200 | T17: =+K17 -> 3000 | U17: J | AA17: PENSION SCGS MENSUAL | AF17: =+AF15*0.001*AF16 -> 308.56958 | AG17: V=(T/1000)*U | BH17: AHORRO PENSIONAL EDAD JUBILACION | BM17: =+VLOOKUP(AF11,$R$28:$Y$76,8,FALSE) -> 11403.062
B18: CRECIMIENTO SALARIAL CADA DOS AÑOS | F18: 0 | I18: CUOTAS | J18: =+BM2 -> 240 | K18: PENSION MENSUAL SEBD | L18: =+MIN(J17*J20/12,F16) -> 210 | M18: G=(F*E)/12 | R18: CUOTAS | S18: =+J18 -> 240 | T18: PENSION MENSUAL 1er pilarBD | U18: =+(K17*S20)/12 -> 150 | V18: K=(E*J)/12 | W18: REEMPLAZO MEJ.AÑOS | X18: =+U22/(J17/12) -> 0.59650045 | Y18: P=O/(E/12) | AA18: REEMPLAZO MEJ.AÑOS | AF18: =+AF17/(J17/12) -> 0.88162736 | AG18: W=V/(E/12) | BH18: FACTOR DE PENSIONAMIENTO XMIL | BM18: =+AF16 -> 5.1543312
B19: SALARIO INICIAL | F19: =+salidaformulas!A10 -> 700 | H19: D | I19: EXCESO DENSIDAD | J19: =+BM3 -> 0 | K19: SALARIO PROMEDIO TOTAL MENSUAL COTIZADO | L19: =+F23 -> 350 | M19: H | R19: EXCESO DENSIDAD | S19: =+J19 -> 0 | T19: AHORRO PERSONAL | U19: =+BM17 -> 11403.062 | V19: L | W19: SALARIO PROMEDIO TOTAL MENSUAL COTIZADO | X19: =+L19 -> 350 | Y19: =+M19 -> H | AA19: SALARIO PROMEDIO TOTAL MENSUAL COTIZADO | AF19: =+X19 -> 350 | AG19: H | BH19: PENSION MENSUAL 2do PILAR | BM19: =+(BM17/1000)*BM18 -> 58.775157
B20: cuotas pagadas por año | F20: 6 | H20: E=B+C*D | I20: REEMPLAZO MEJ.AÑOS | J20: =+BM4 -> 0.6 | K20: TASA BRUTA REEMPLAZO | L20: =+L18/L19 -> 0.6 | M20: I=G/H | Q20: E | R20: REEMPLAZO MEJ.AÑOS | S20: =+J20 -> 0.6 | T20: FACTOR PENSIONAMIENTO VITALICIO | U20: =+BM18 -> 5.1543312 | V20: M | W20: TASA BRUTA REEMPLAZO | X20: =+U22/L19 -> 0.59650045 | Y20: Q=O/H | AA20: TASA BRUTA REEMPLAZO | AF20: =+AF17/L19 -> 0.88162736 | AG20: X=V/H | BH20: PENSION FINAL SISTEMA MIXTO | BM20: =IF(BM2>=240,MAX(BM16+BM19,265),BM16+BM19) -> 265
C21: TOTAL CUOTAS MENSUALES | F21: =+SUMIF(F28:F76,">0") -> 240 | G21: =+F21/12 -> 20 | T21: PENSION MENSUAL 2do PILAR | U21: =+U19*0.001*U20 -> 58.775157 | V21: N=(L/1000)*M | BH21: TASA DE REEMPLAZO FINAL DE ESTE CALCULO | BM21: =+BM20*12/VLOOKUP(MAX($BL$8:$BL$10),$BL$8:$BN$10,2,0) -> 0.75714286
C22: SALARIO PROMEDIO ANNUAL | F22: =+AVERAGEIF(G28:G76,">0") -> 4200 | T22: PENSION TOTAL A RECIBIR | U22: =+U21+U18 -> 208.77516 | V22: O=N+K
C23: PROMEDIO MENSUALIZADO | F23: =+F22/12 -> 350 | T23: tasa capitalizacion mixto | U23: 0.04
B24: Tabla 1 | I24: Tabla 2 | Q24: Tabla 3 | AA24: Tabla 4 | AK24: Tabla 5 | AV24: Tabla 6
B25: Datos Básicos | I25: SALARIOS PARA CALCULO PROMEDIO MEJORES | Q25: SISTEMA DE ACUMULACION DEL SISTEMA MIXTO | AA25: ACUMULACION SCGS ANTES DE LA ENTRADA EN VIGENCIA | AK25: ACUMULACION SCGS DESPUES DE LA ENTRADA EN VIGENCIA | AV25: ACUMULACION DESDE EL INICIO DENTRO DEL SISTEMA DE CAPITALIZACION CON GARANTIA SOLIDARIA
B26: AÑO | C26: EDAD INI AÑO | D26: CREC. SALARIO | E26: SALARIO MENSUAL | F26: CUOTAS APORTADAS | G26: SALARIO ANUAL | I26: AÑO | J26: EDAD | K26: CUOTAS APORTADAS | L26: SALARIO COTIZADO 1er PILAR SISTEMA MIXTO ANUAL | M26: SALARIO COTIZADO SEGUNDO PILAR ANUAL | N26: SALARIO COTIZADO PARA PROMEDIO ANUAL | O26: SALARIO COTIZADO PARA PROMEDIO MENSUAL | Q26: AÑO | R26: EDAD FIN AÑO | S26: INDICADOR | T26: TASA O-P SALARIO | U26: SALARIO SEGUNDO PILAR | V26: AHORRO PENSIONAL INICIAL | W26: APORTES | X26: INTERESES | Y26: AHORRO PENSIONAL FINAL | AA26: AÑO | AB26: EDAD FIN AÑO | AC26: INDICADOR | AD26: TASA O-P SALARIO | AE26: SALARIO ANUAL CON MAX 2500 MENSUAL | AF26: AHORRO PENSIONAL INICIAL | AG26: APORTES | AH26: INTERESES | AI26: AHORRO PENSIONAL FINAL | AK26: AÑO | AL26: EDAD FIN AÑO | AM26: INDICADOR | AN26: TASA O-P SALARIO | AO26: TASA O-P XIII | AP26: SALARIO ANUAL SIN MAXIMO | AQ26: AHORRO PENSIONAL INICIAL | AR26: APORTES | AS26: INTERESES | AT26: AHORRO PENSIONAL INICIAL | AV26: AÑO | AW26: EDAD FIN AÑO | AX26: INDICADOR | AY26: TASA O-P SALARIO | AZ26: TASA O-P XIII | BA26: SALARIO ANUAL SIN MAXIMO | BB26: AHORRO PENSIONAL INICIAL | BC26: APORTES | BD26: INTERESES | BE26: AHORRO PENSIONAL INICIAL
B28: 1 | C28: =+F4 -> 22 | D28: 1 | E28: =+IF($C28>=$F$6,0,$F$19*D28) -> 700 | F28: =+IF($C28>=$F$6,0,$F$20) -> 6 | G28: =+E28*F28 -> 4200 | I28: =+B28 -> 1 | J28: =+C28 -> 22 | K28: =+IF(AL28<=$AF$11,1,0)*F28 -> 6 | L28: =+IF(AL28>$AF$11,0,IF(E28>500,500*F28,E28*F28)) -> 3000 | M28: =+IF(AL28>$AF$11,0,IF(G28-L28 <= 0,0,G28-L28)) -> 1200 | N28: =+IF($F$7<7,L28+M28,IF(AL28>$AF$11,0,IF($F$2=1,IF($J28<$F$5,IF(G28<=$F$16*12,G28,$F$16*12),G28),G28))) -> 4200 | O28: =+IFERROR(N28/K28,0) -> 700 | Q28: =+I28 -> 1 | R28: =+J28+1 -> 23 | S28: =+IF(R28<=$AF$11,1,0) -> 1 | T28: =+$F$9-$F$17 -> 0.1 | U28: =+M28 -> 1200 | V28: =+Y27 -> 0 | W28: =+T28*U28*S28 -> 120 | X28: =+$U$23*V28 -> 0 | Y28: =+(V28+W28+X28) -> 120 | AA28: =+B28 -> 1 | AB28: =+C28+1 -> 23 | AC28: =+IF(C28<$F$5,1,0) -> 0 | AD28: =F8 -> 0.15 | AE28: =+IF($F$2=1,IF(G28<=2500*12,G28,2500*12),G28) -> 4200 | AF28: =+AI27 -> 0 | AG28: =+AD28*AE28*$AC28 -> 0 | AH28: =+AF28*$F$11 -> 0 | AI28: =+(AF28+AG28+AH28) -> 0 | AK28: =+AA28 -> 1 | AL28: =+AB28 -> 23 | AM28: =+IF($C28>=$F$5,1,0) -> 1 | AN28: =+$F$9*AM28 -> 0.135 | AO28: =+AM28*$F$10 -> 0.18 | AP28: =+G28 -> 4200 | AQ28: =+AT27 -> 0 | AR28: =+(AN28*AP28+AO28*(AP28/12))*AM28 -> 630 | AS28: =+AQ28*$F$12 -> 0 | AT28: =+(AQ28+AR28+AS28) -> 630 | AV28: =+AK28 -> 1 | AW28: =+AL28 -> 23 | AX28: 1 | AY28: =+$F$9*AX28 -> 0.135 | AZ28: =+AX28*$F$10 -> 0.18 | BA28: =+G28 -> 4200 | BB28: =+BE27 -> 0 | BC28: =+(AY28*BA28+AZ28*(BA28/12))*AX28 -> 630 | BD28: =+BB28*$F$12 -> 0 | BE28: =+(BB28+BC28+BD28) -> 630
B29: =+B28+1 -> 2 | C29: =+C28+1 -> 23 | D29: =+D28*(1+$F$18) -> 1 | E29: =+IF($C29>=$F$6,0,$F$19*D29) -> 700 | F29: =+IF($C29>=$F$6,0,$F$20) -> 6 | G29: =+E29*F29 -> 4200 | I29: =+I28+1 -> 2 | J29: =+C29 -> 23 | K29: =+IF(AL29<=$AF$11,1,0)*F29 -> 6 | L29: =+IF(AL29>$AF$11,0,IF(E29>500,500*F29,E29*F29)) -> 3000 | M29: =+IF(AL29>$AF$11,0,IF(G29-L29 <= 0,0,G29-L29)) -> 1200 | N29: =+IF($F$7<7,L29+M29,IF(AL29>$AF$11,0,IF($F$2=1,IF($J29<$F$5,IF(G29<=$F$16*12,G29,$F$16*12),G29),G29))) -> 4200 | O29: =+IFERROR(N29/K29,0) -> 700 | Q29: =+I29 -> 2 | R29: =+J29+1 -> 24 | S29: =+IF(R29<=$AF$11,1,0) -> 1 | T29: =+T28 -> 0.1 | U29: =+M29 -> 1200 | V29: =+Y28 -> 120 | W29: =+T29*U29*S29 -> 120 | X29: =+$U$23*V29 -> 4.8 | Y29: =+(V29+W29+X29) -> 244.8 | AA29: =+B29 -> 2 | AB29: =+C29+1 -> 24 | AC29: =+IF(C29<$F$5,1,0) -> 0 | AD29: =+AD28 -> 0.15 | AE29: =+IF($F$2=1,IF(G29<=2500*12,G29,2500*12),G29) -> 4200 | AF29: =+AI28 -> 0 | AG29: =+AD29*AE29*$AC29 -> 0 | AH29: =+AF29*$F$11 -> 0 | AI29: =+(AF29+AG29+AH29) -> 0 | AK29: =+AA29 -> 2 | AL29: =+AB29 -> 24 | AM29: =+IF($C29>=$F$5,1,0) -> 1 | AN29: =+$F$9*AM29 -> 0.135 | AO29: =+AM29*$F$10 -> 0.18 | AP29: =+G29 -> 4200 | AQ29: =+AT28 -> 630 | AR29: =+(AN29*AP29+AO29*(AP29/12))*AM29 -> 630 | AS29: =+AQ29*$F$12 -> 25.2 | AT29: =+(AQ29+AR29+AS29) -> 1285.2 | AV29: =+AK29 -> 2 | AW29: =+AL29 -> 24 | AX29: 1 | AY29: =+$F$9*AX29 -> 0.135 | AZ29: =+AX29*$F$10 -> 0.18 | BA29: =+G29 -> 4200 | BB29: =+BE28 -> 630 | BC29: =+(AY29*BA29+AZ29*(BA29/12))*AX29 -> 630 | BD29: =+BB29*$F$12 -> 25.2 | BE29: =+(BB29+BC29+BD29) -> 1285.2
B30: =+B29+1 -> 3 | C30: =+C29+1 -> 24 | D30: =+D29*(1+$F$18) -> 1 | E30: =+IF($C30>=$F$6,0,$F$19*D30) -> 700 | F30: =+IF($C30>=$F$6,0,$F$20) -> 6 | G30: =+E30*F30 -> 4200 | I30: =+I29+1 -> 3 | J30: =+C30 -> 24 | K30: =+IF(AL30<=$AF$11,1,0)*F30 -> 6 | L30: =+IF(AL30>$AF$11,0,IF(E30>500,500*F30,E30*F30)) -> 3000 | M30: =+IF(AL30>$AF$11,0,IF(G30-L30 <= 0,0,G30-L30)) -> 1200 | N30: =+IF($F$7<7,L30+M30,IF(AL30>$AF$11,0,IF($F$2=1,IF($J30<$F$5,IF(G30<=$F$16*12,G30,$F$16*12),G30),G30))) -> 4200 | O30: =+IFERROR(N30/K30,0) -> 700 | Q30: =+I30 -> 3 | R30: =+J30+1 -> 25 | S30: =+IF(R30<=$AF$11,1,0) -> 1 | T30: =+T29 -> 0.1 | U30: =+M30 -> 1200 | V30: =+Y29 -> 244.8 | W30: =+T30*U30*S30 -> 120 | X30: =+$U$23*V30 -> 9.792 | Y30: =+(V30+W30+X30) -> 374.592 | AA30: =+B30 -> 3 | AB30: =+C30+1 -> 25 | AC30: =+IF(C30<$F$5,1,0) -> 0 | AD30: =+AD29 -> 0.15 | AE30: =+IF($F$2=1,IF(G30<=2500*12,G30,2500*12),G30) -> 4200 | AF30: =+AI29 -> 0 | AG30: =+AD30*AE30*$AC30 -> 0 | AH30: =+AF30*$F$11 -> 0 | AI30: =+(AF30+AG30+AH30) -> 0 | AK30: =+AA30 -> 3 | AL30: =+AB30 -> 25 | AM30: =+IF($C30>=$F$5,1,0) -> 1 | AN30: =+$F$9*AM30 -> 0.135 | AO30: =+AM30*$F$10 -> 0.18 | AP30: =+G30 -> 4200 | AQ30: =+AT29 -> 1285.2 | AR30: =+(AN30*AP30+AO30*(AP30/12))*AM30 -> 630 | AS30: =+AQ30*$F$12 -> 51.408 | AT30: =+(AQ30+AR30+AS30) -> 1966.608 | AV30: =+AK30 -> 3 | AW30: =+AL30 -> 25 | AX30: 1 | AY30: =+$F$9*AX30 -> 0.135 | AZ30: =+AX30*$F$10 -> 0.18 | BA30: =+G30 -> 4200 | BB30: =+BE29 -> 1285.2 | BC30: =+(AY30*BA30+AZ30*(BA30/12))*AX30 -> 630 | BD30: =+BB30*$F$12 -> 51.408 | BE30: =+(BB30+BC30+BD30) -> 1966.608
B31: =+B30+1 -> 4 | C31: =+C30+1 -> 25 | D31: =+D30*(1+$F$18) -> 1 | E31: =+IF($C31>=$F$6,0,$F$19*D31) -> 700 | F31: =+IF($C31>=$F$6,0,$F$20) -> 6 | G31: =+E31*F31 -> 4200 | I31: =+I30+1 -> 4 | J31: =+C31 -> 25 | K31: =+IF(AL31<=$AF$11,1,0)*F31 -> 6 | L31: =+IF(AL31>$AF$11,0,IF(E31>500,500*F31,E31*F31)) -> 3000 | M31: =+IF(AL31>$AF$11,0,IF(G31-L31 <= 0,0,G31-L31)) -> 1200 | N31: =+IF($F$7<7,L31+M31,IF(AL31>$AF$11,0,IF($F$2=1,IF($J31<$F$5,IF(G31<=$F$16*12,G31,$F$16*12),G31),G31))) -> 4200 | O31: =+IFERROR(N31/K31,0) -> 700 | Q31: =+I31 -> 4 | R31: =+J31+1 -> 26 | S31: =+IF(R31<=$AF$11,1,0) -> 1 | T31: =+T30 -> 0.1 | U31: =+M31 -> 1200 | V31: =+Y30 -> 374.592 | W31: =+T31*U31*S31 -> 120 | X31: =+$U$23*V31 -> 14.98368 | Y31: =+(V31+W31+X31) -> 509.57568 | AA31: =+B31 -> 4 | AB31: =+C31+1 -> 26 | AC31: =+IF(C31<$F$5,1,0) -> 0 | AD31: =+AD30 -> 0.15 | AE31: =+IF($F$2=1,IF(G31<=2500*12,G31,2500*12),G31) -> 4200 | AF31: =+AI30 -> 0 | AG31: =+AD31*AE31*$AC31 -> 0 | AH31: =+AF31*$F$11 -> 0 | AI31: =+(AF31+AG31+AH31) -> 0 | AK31: =+AA31 -> 4 | AL31: =+AB31 -> 26 | AM31: =+IF($C31>=$F$5,1,0) -> 1 | AN31: =+$F$9*AM31 -> 0.135 | AO31: =+AM31*$F$10 -> 0.18 | AP31: =+G31 -> 4200 | AQ31: =+AT30 -> 1966.608 | AR31: =+(AN31*AP31+AO31*(AP31/12))*AM31 -> 630 | AS31: =+AQ31*$F$12 -> 78.66432 | AT31: =+(AQ31+AR31+AS31) -> 2675.2723 | AV31: =+AK31 -> 4 | AW31: =+AL31 -> 26 | AX31: 1 | AY31: =+$F$9*AX31 -> 0.135 | AZ31: =+AX31*$F$10 -> 0.18 | BA31: =+G31 -> 4200 | BB31: =+BE30 -> 1966.608 | BC31: =+(AY31*BA31+AZ31*(BA31/12))*AX31 -> 630 | BD31: =+BB31*$F$12 -> 78.66432 | BE31: =+(BB31+BC31+BD31) -> 2675.2723
B32: =+B31+1 -> 5 | C32: =+C31+1 -> 26 | D32: =+D31*(1+$F$18) -> 1 | E32: =+IF($C32>=$F$6,0,$F$19*D32) -> 700 | F32: =+IF($C32>=$F$6,0,$F$20) -> 6 | G32: =+E32*F32 -> 4200 | I32: =+I31+1 -> 5 | J32: =+C32 -> 26 | K32: =+IF(AL32<=$AF$11,1,0)*F32 -> 6 | L32: =+IF(AL32>$AF$11,0,IF(E32>500,500*F32,E32*F32)) -> 3000 | M32: =+IF(AL32>$AF$11,0,IF(G32-L32 <= 0,0,G32-L32)) -> 1200 | N32: =+IF($F$7<7,L32+M32,IF(AL32>$AF$11,0,IF($F$2=1,IF($J32<$F$5,IF(G32<=$F$16*12,G32,$F$16*12),G32),G32))) -> 4200 | O32: =+IFERROR(N32/K32,0) -> 700 | Q32: =+I32 -> 5 | R32: =+J32+1 -> 27 | S32: =+IF(R32<=$AF$11,1,0) -> 1 | T32: =+T31 -> 0.1 | U32: =+M32 -> 1200 | V32: =+Y31 -> 509.57568 | W32: =+T32*U32*S32 -> 120 | X32: =+$U$23*V32 -> 20.383027 | Y32: =+(V32+W32+X32) -> 649.95871 | AA32: =+B32 -> 5 | AB32: =+C32+1 -> 27 | AC32: =+IF(C32<$F$5,1,0) -> 0 | AD32: =+AD31 -> 0.15 | AE32: =+IF($F$2=1,IF(G32<=2500*12,G32,2500*12),G32) -> 4200 | AF32: =+AI31 -> 0 | AG32: =+AD32*AE32*$AC32 -> 0 | AH32: =+AF32*$F$11 -> 0 | AI32: =+(AF32+AG32+AH32) -> 0 | AK32: =+AA32 -> 5 | AL32: =+AB32 -> 27 | AM32: =+IF($C32>=$F$5,1,0) -> 1 | AN32: =+$F$9*AM32 -> 0.135 | AO32: =+AM32*$F$10 -> 0.18 | AP32: =+G32 -> 4200 | AQ32: =+AT31 -> 2675.2723 | AR32: =+(AN32*AP32+AO32*(AP32/12))*AM32 -> 630 | AS32: =+AQ32*$F$12 -> 107.01089 | AT32: =+(AQ32+AR32+AS32) -> 3412.2832 | AV32: =+AK32 -> 5 | AW32: =+AL32 -> 27 | AX32: 1 | AY32: =+$F$9*AX32 -> 0.135 | AZ32: =+AX32*$F$10 -> 0.18 | BA32: =+G32 -> 4200 | BB32: =+BE31 -> 2675.2723 | BC32: =+(AY32*BA32+AZ32*(BA32/12))*AX32 -> 630 | BD32: =+BB32*$F$12 -> 107.01089 | BE32: =+(BB32+BC32+BD32) -> 3412.2832
B33: =+B32+1 -> 6 | C33: =+C32+1 -> 27 | D33: =+D32*(1+$F$18) -> 1 | E33: =+IF($C33>=$F$6,0,$F$19*D33) -> 700 | F33: =+IF($C33>=$F$6,0,$F$20) -> 6 | G33: =+E33*F33 -> 4200 | I33: =+I32+1 -> 6 | J33: =+C33 -> 27 | K33: =+IF(AL33<=$AF$11,1,0)*F33 -> 6 | L33: =+IF(AL33>$AF$11,0,IF(E33>500,500*F33,E33*F33)) -> 3000 | M33: =+IF(AL33>$AF$11,0,IF(G33-L33 <= 0,0,G33-L33)) -> 1200 | N33: =+IF($F$7<7,L33+M33,IF(AL33>$AF$11,0,IF($F$2=1,IF($J33<$F$5,IF(G33<=$F$16*12,G33,$F$16*12),G33),G33))) -> 4200 | O33: =+IFERROR(N33/K33,0) -> 700 | Q33: =+I33 -> 6 | R33: =+J33+1 -> 28 | S33: =+IF(R33<=$AF$11,1,0) -> 1 | T33: =+T32 -> 0.1 | U33: =+M33 -> 1200 | V33: =+Y32 -> 649.95871 | W33: =+T33*U33*S33 -> 120 | X33: =+$U$23*V33 -> 25.998348 | Y33: =+(V33+W33+X33) -> 795.95706 | AA33: =+B33 -> 6 | AB33: =+C33+1 -> 28 | AC33: =+IF(C33<$F$5,1,0) -> 0 | AD33: =+AD32 -> 0.15 | AE33: =+IF($F$2=1,IF(G33<=2500*12,G33,2500*12),G33) -> 4200 | AF33: =+AI32 -> 0 | AG33: =+AD33*AE33*$AC33 -> 0 | AH33: =+AF33*$F$11 -> 0 | AI33: =+(AF33+AG33+AH33) -> 0 | AK33: =+AA33 -> 6 | AL33: =+AB33 -> 28 | AM33: =+IF($C33>=$F$5,1,0) -> 1 | AN33: =+$F$9*AM33 -> 0.135 | AO33: =+AM33*$F$10 -> 0.18 | AP33: =+G33 -> 4200 | AQ33: =+AT32 -> 3412.2832 | AR33: =+(AN33*AP33+AO33*(AP33/12))*AM33 -> 630 | AS33: =+AQ33*$F$12 -> 136.49133 | AT33: =+(AQ33+AR33+AS33) -> 4178.7745 | AV33: =+AK33 -> 6 | AW33: =+AL33 -> 28 | AX33: 1 | AY33: =+$F$9*AX33 -> 0.135 | AZ33: =+AX33*$F$10 -> 0.18 | BA33: =+G33 -> 4200 | BB33: =+BE32 -> 3412.2832 | BC33: =+(AY33*BA33+AZ33*(BA33/12))*AX33 -> 630 | BD33: =+BB33*$F$12 -> 136.49133 | BE33: =+(BB33+BC33+BD33) -> 4178.7745
B34: =+B33+1 -> 7 | C34: =+C33+1 -> 28 | D34: =+D33*(1+$F$18) -> 1 | E34: =+IF($C34>=$F$6,0,$F$19*D34) -> 700 | F34: =+IF($C34>=$F$6,0,$F$20) -> 6 | G34: =+E34*F34 -> 4200 | I34: =+I33+1 -> 7 | J34: =+C34 -> 28 | K34: =+IF(AL34<=$AF$11,1,0)*F34 -> 6 | L34: =+IF(AL34>$AF$11,0,IF(E34>500,500*F34,E34*F34)) -> 3000 | M34: =+IF(AL34>$AF$11,0,IF(G34-L34 <= 0,0,G34-L34)) -> 1200 | N34: =+IF($F$7<7,L34+M34,IF(AL34>$AF$11,0,IF($F$2=1,IF($J34<$F$5,IF(G34<=$F$16*12,G34,$F$16*12),G34),G34))) -> 4200 | O34: =+IFERROR(N34/K34,0) -> 700 | Q34: =+I34 -> 7 | R34: =+J34+1 -> 29 | S34: =+IF(R34<=$AF$11,1,0) -> 1 | T34: =+T33 -> 0.1 | U34: =+M34 -> 1200 | V34: =+Y33 -> 795.95706 | W34: =+T34*U34*S34 -> 120 | X34: =+$U$23*V34 -> 31.838282 | Y34: =+(V34+W34+X34) -> 947.79534 | AA34: =+B34 -> 7 | AB34: =+C34+1 -> 29 | AC34: =+IF(C34<$F$5,1,0) -> 0 | AD34: =+AD33 -> 0.15 | AE34: =+IF($F$2=1,IF(G34<=2500*12,G34,2500*12),G34) -> 4200 | AF34: =+AI33 -> 0 | AG34: =+AD34*AE34*$AC34 -> 0 | AH34: =+AF34*$F$11 -> 0 | AI34: =+(AF34+AG34+AH34) -> 0 | AK34: =+AA34 -> 7 | AL34: =+AB34 -> 29 | AM34: =+IF($C34>=$F$5,1,0) -> 1 | AN34: =+$F$9*AM34 -> 0.135 | AO34: =+AM34*$F$10 -> 0.18 | AP34: =+G34 -> 4200 | AQ34: =+AT33 -> 4178.7745 | AR34: =+(AN34*AP34+AO34*(AP34/12))*AM34 -> 630 | AS34: =+AQ34*$F$12 -> 167.15098 | AT34: =+(AQ34+AR34+AS34) -> 4975.9255 | AV34: =+AK34 -> 7 | AW34: =+AL34 -> 29 | AX34: 1 | AY34: =+$F$9*AX34 -> 0.135 | AZ34: =+AX34*$F$10 -> 0.18 | BA34: =+G34 -> 4200 | BB34: =+BE33 -> 4178.7745 | BC34: =+(AY34*BA34+AZ34*(BA34/12))*AX34 -> 630 | BD34: =+BB34*$F$12 -> 167.15098 | BE34: =+(BB34+BC34+BD34) -> 4975.9255
B35: =+B34+1 -> 8 | C35: =+C34+1 -> 29 | D35: =+D34*(1+$F$18) -> 1 | E35: =+IF($C35>=$F$6,0,$F$19*D35) -> 700 | F35: =+IF($C35>=$F$6,0,$F$20) -> 6 | G35: =+E35*F35 -> 4200 | I35: =+I34+1 -> 8 | J35: =+C35 -> 29 | K35: =+IF(AL35<=$AF$11,1,0)*F35 -> 6 | L35: =+IF(AL35>$AF$11,0,IF(E35>500,500*F35,E35*F35)) -> 3000 | M35: =+IF(AL35>$AF$11,0,IF(G35-L35 <= 0,0,G35-L35)) -> 1200 | N35: =+IF($F$7<7,L35+M35,IF(AL35>$AF$11,0,IF($F$2=1,IF($J35<$F$5,IF(G35<=$F$16*12,G35,$F$16*12),G35),G35))) -> 4200 | O35: =+IFERROR(N35/K35,0) -> 700 | Q35: =+I35 -> 8 | R35: =+J35+1 -> 30 | S35: =+IF(R35<=$AF$11,1,0) -> 1 | T35: =+T34 -> 0.1 | U35: =+M35 -> 1200 | V35: =+Y34 -> 947.79534 | W35: =+T35*U35*S35 -> 120 | X35: =+$U$23*V35 -> 37.911814 | Y35: =+(V35+W35+X35) -> 1105.7072 | AA35: =+B35 -> 8 | AB35: =+C35+1 -> 30 | AC35: =+IF(C35<$F$5,1,0) -> 0 | AD35: =+AD34 -> 0.15 | AE35: =+IF($F$2=1,IF(G35<=2500*12,G35,2500*12),G35) -> 4200 | AF35: =+AI34 -> 0 | AG35: =+AD35*AE35*$AC35 -> 0 | AH35: =+AF35*$F$11 -> 0 | AI35: =+(AF35+AG35+AH35) -> 0 | AK35: =+AA35 -> 8 | AL35: =+AB35 -> 30 | AM35: =+IF($C35>=$F$5,1,0) -> 1 | AN35: =+$F$9*AM35 -> 0.135 | AO35: =+AM35*$F$10 -> 0.18 | AP35: =+G35 -> 4200 | AQ35: =+AT34 -> 4975.9255 | AR35: =+(AN35*AP35+AO35*(AP35/12))*AM35 -> 630 | AS35: =+AQ35*$F$12 -> 199.03702 | AT35: =+(AQ35+AR35+AS35) -> 5804.9625 | AV35: =+AK35 -> 8 | AW35: =+AL35 -> 30 | AX35: 1 | AY35: =+$F$9*AX35 -> 0.135 | AZ35: =+AX35*$F$10 -> 0.18 | BA35: =+G35 -> 4200 | BB35: =+BE34 -> 4975.9255 | BC35: =+(AY35*BA35+AZ35*(BA35/12))*AX35 -> 630 | BD35: =+BB35*$F$12 -> 199.03702 | BE35: =+(BB35+BC35+BD35) -> 5804.9625
B36: =+B35+1 -> 9 | C36: =+C35+1 -> 30 | D36: =+D35*(1+$F$18) -> 1 | E36: =+IF($C36>=$F$6,0,$F$19*D36) -> 700 | F36: =+IF($C36>=$F$6,0,$F$20) -> 6 | G36: =+E36*F36 -> 4200 | I36: =+I35+1 -> 9 | J36: =+C36 -> 30 | K36: =+IF(AL36<=$AF$11,1,0)*F36 -> 6 | L36: =+IF(AL36>$AF$11,0,IF(E36>500,500*F36,E36*F36)) -> 3000 | M36: =+IF(AL36>$AF$11,0,IF(G36-L36 <= 0,0,G36-L36)) -> 1200 | N36: =+IF($F$7<7,L36+M36,IF(AL36>$AF$11,0,IF($F$2=1,IF($J36<$F$5,IF(G36<=$F$16*12,G36,$F$16*12),G36),G36))) -> 4200 | O36: =+IFERROR(N36/K36,0) -> 700 | Q36: =+I36 -> 9 | R36: =+J36+1 -> 31 | S36: =+IF(R36<=$AF$11,1,0) -> 1 | T36: =+T35 -> 0.1 | U36: =+M36 -> 1200 | V36: =+Y35 -> 1105.7072 | W36: =+T36*U36*S36 -> 120 | X36: =+$U$23*V36 -> 44.228286 | Y36: =+(V36+W36+X36) -> 1269.9354 | AA36: =+B36 -> 9 | AB36: =+C36+1 -> 31 | AC36: =+IF(C36<$F$5,1,0) -> 0 | AD36: =+AD35 -> 0.15 | AE36: =+IF($F$2=1,IF(G36<=2500*12,G36,2500*12),G36) -> 4200 | AF36: =+AI35 -> 0 | AG36: =+AD36*AE36*$AC36 -> 0 | AH36: =+AF36*$F$11 -> 0 | AI36: =+(AF36+AG36+AH36) -> 0 | AK36: =+AA36 -> 9 | AL36: =+AB36 -> 31 | AM36: =+IF($C36>=$F$5,1,0) -> 1 | AN36: =+$F$9*AM36 -> 0.135 | AO36: =+AM36*$F$10 -> 0.18 | AP36: =+G36 -> 4200 | AQ36: =+AT35 -> 5804.9625 | AR36: =+(AN36*AP36+AO36*(AP36/12))*AM36 -> 630 | AS36: =+AQ36*$F$12 -> 232.1985 | AT36: =+(AQ36+AR36+AS36) -> 6667.161 | AV36: =+AK36 -> 9 | AW36: =+AL36 -> 31 | AX36: 1 | AY36: =+$F$9*AX36 -> 0.135 | AZ36: =+AX36*$F$10 -> 0.18 | BA36: =+G36 -> 4200 | BB36: =+BE35 -> 5804.9625 | BC36: =+(AY36*BA36+AZ36*(BA36/12))*AX36 -> 630 | BD36: =+BB36*$F$12 -> 232.1985 | BE36: =+(BB36+BC36+BD36) -> 6667.161
B37: =+B36+1 -> 10 | C37: =+C36+1 -> 31 | D37: =+D36*(1+$F$18) -> 1 | E37: =+IF($C37>=$F$6,0,$F$19*D37) -> 700 | F37: =+IF($C37>=$F$6,0,$F$20) -> 6 | G37: =+E37*F37 -> 4200 | I37: =+I36+1 -> 10 | J37: =+C37 -> 31 | K37: =+IF(AL37<=$AF$11,1,0)*F37 -> 6 | L37: =+IF(AL37>$AF$11,0,IF(E37>500,500*F37,E37*F37)) -> 3000 | M37: =+IF(AL37>$AF$11,0,IF(G37-L37 <= 0,0,G37-L37)) -> 1200 | N37: =+IF($F$7<7,L37+M37,IF(AL37>$AF$11,0,IF($F$2=1,IF($J37<$F$5,IF(G37<=$F$16*12,G37,$F$16*12),G37),G37))) -> 4200 | O37: =+IFERROR(N37/K37,0) -> 700 | Q37: =+I37 -> 10 | R37: =+J37+1 -> 32 | S37: =+IF(R37<=$AF$11,1,0) -> 1 | T37: =+T36 -> 0.1 | U37: =+M37 -> 1200 | V37: =+Y36 -> 1269.9354 | W37: =+T37*U37*S37 -> 120 | X37: =+$U$23*V37 -> 50.797417 | Y37: =+(V37+W37+X37) -> 1440.7329 | AA37: =+B37 -> 10 | AB37: =+C37+1 -> 32 | AC37: =+IF(C37<$F$5,1,0) -> 0 | AD37: =+AD36 -> 0.15 | AE37: =+IF($F$2=1,IF(G37<=2500*12,G37,2500*12),G37) -> 4200 | AF37: =+AI36 -> 0 | AG37: =+AD37*AE37*$AC37 -> 0 | AH37: =+AF37*$F$11 -> 0 | AI37: =+(AF37+AG37+AH37) -> 0 | AK37: =+AA37 -> 10 | AL37: =+AB37 -> 32 | AM37: =+IF($C37>=$F$5,1,0) -> 1 | AN37: =+$F$9*AM37 -> 0.135 | AO37: =+AM37*$F$10 -> 0.18 | AP37: =+G37 -> 4200 | AQ37: =+AT36 -> 6667.161 | AR37: =+(AN37*AP37+AO37*(AP37/12))*AM37 -> 630 | AS37: =+AQ37*$F$12 -> 266.68644 | AT37: =+(AQ37+AR37+AS37) -> 7563.8475 | AV37: =+AK37 -> 10 | AW37: =+AL37 -> 32 | AX37: 1 | AY37: =+$F$9*AX37 -> 0.135 | AZ37: =+AX37*$F$10 -> 0.18 | BA37: =+G37 -> 4200 | BB37: =+BE36 -> 6667.161 | BC37: =+(AY37*BA37+AZ37*(BA37/12))*AX37 -> 630 | BD37: =+BB37*$F$12 -> 266.68644 | BE37: =+(BB37+BC37+BD37) -> 7563.8475
B38: =+B37+1 -> 11 | C38: =+C37+1 -> 32 | D38: =+D37*(1+$F$18) -> 1 | E38: =+IF($C38>=$F$6,0,$F$19*D38) -> 700 | F38: =+IF($C38>=$F$6,0,$F$20) -> 6 | G38: =+E38*F38 -> 4200 | I38: =+I37+1 -> 11 | J38: =+C38 -> 32 | K38: =+IF(AL38<=$AF$11,1,0)*F38 -> 6 | L38: =+IF(AL38>$AF$11,0,IF(E38>500,500*F38,E38*F38)) -> 3000 | M38: =+IF(AL38>$AF$11,0,IF(G38-L38 <= 0,0,G38-L38)) -> 1200 | N38: =+IF($F$7<7,L38+M38,IF(AL38>$AF$11,0,IF($F$2=1,IF($J38<$F$5,IF(G38<=$F$16*12,G38,$F$16*12),G38),G38))) -> 4200 | O38: =+IFERROR(N38/K38,0) -> 700 | Q38: =+I38 -> 11 | R38: =+J38+1 -> 33 | S38: =+IF(R38<=$AF$11,1,0) -> 1 | T38: =+T37 -> 0.1 | U38: =+M38 -> 1200 | V38: =+Y37 -> 1440.7329 | W38: =+T38*U38*S38 -> 120 | X38: =+$U$23*V38 -> 57.629314 | Y38: =+(V38+W38+X38) -> 1618.3622 | AA38: =+B38 -> 11 | AB38: =+C38+1 -> 33 | AC38: =+IF(C38<$F$5,1,0) -> 0 | AD38: =+AD37 -> 0.15 | AE38: =+IF($F$2=1,IF(G38<=2500*12,G38,2500*12),G38) -> 4200 | AF38: =+AI37 -> 0 | AG38: =+AD38*AE38*$AC38 -> 0 | AH38: =+AF38*$F$11 -> 0 | AI38: =+(AF38+AG38+AH38) -> 0 | AK38: =+AA38 -> 11 | AL38: =+AB38 -> 33 | AM38: =+IF($C38>=$F$5,1,0) -> 1 | AN38: =+$F$9*AM38 -> 0.135 | AO38: =+AM38*$F$10 -> 0.18 | AP38: =+G38 -> 4200 | AQ38: =+AT37 -> 7563.8475 | AR38: =+(AN38*AP38+AO38*(AP38/12))*AM38 -> 630 | AS38: =+AQ38*$F$12 -> 302.5539 | AT38: =+(AQ38+AR38+AS38) -> 8496.4014 | AV38: =+AK38 -> 11 | AW38: =+AL38 -> 33 | AX38: 1 | AY38: =+$F$9*AX38 -> 0.135 | AZ38: =+AX38*$F$10 -> 0.18 | BA38: =+G38 -> 4200 | BB38: =+BE37 -> 7563.8475 | BC38: =+(AY38*BA38+AZ38*(BA38/12))*AX38 -> 630 | BD38: =+BB38*$F$12 -> 302.5539 | BE38: =+(BB38+BC38+BD38) -> 8496.4014
B39: =+B38+1 -> 12 | C39: =+C38+1 -> 33 | D39: =+D38*(1+$F$18) -> 1 | E39: =+IF($C39>=$F$6,0,$F$19*D39) -> 700 | F39: =+IF($C39>=$F$6,0,$F$20) -> 6 | G39: =+E39*F39 -> 4200 | I39: =+I38+1 -> 12 | J39: =+C39 -> 33 | K39: =+IF(AL39<=$AF$11,1,0)*F39 -> 6 | L39: =+IF(AL39>$AF$11,0,IF(E39>500,500*F39,E39*F39)) -> 3000 | M39: =+IF(AL39>$AF$11,0,IF(G39-L39 <= 0,0,G39-L39)) -> 1200 | N39: =+IF($F$7<7,L39+M39,IF(AL39>$AF$11,0,IF($F$2=1,IF($J39<$F$5,IF(G39<=$F$16*12,G39,$F$16*12),G39),G39))) -> 4200 | O39: =+IFERROR(N39/K39,0) -> 700 | Q39: =+I39 -> 12 | R39: =+J39+1 -> 34 | S39: =+IF(R39<=$AF$11,1,0) -> 1 | T39: =+T38 -> 0.1 | U39: =+M39 -> 1200 | V39: =+Y38 -> 1618.3622 | W39: =+T39*U39*S39 -> 120 | X39: =+$U$23*V39 -> 64.734487 | Y39: =+(V39+W39+X39) -> 1803.0967 | AA39: =+B39 -> 12 | AB39: =+C39+1 -> 34 | AC39: =+IF(C39<$F$5,1,0) -> 0 | AD39: =+AD38 -> 0.15 | AE39: =+IF($F$2=1,IF(G39<=2500*12,G39,2500*12),G39) -> 4200 | AF39: =+AI38 -> 0 | AG39: =+AD39*AE39*$AC39 -> 0 | AH39: =+AF39*$F$11 -> 0 | AI39: =+(AF39+AG39+AH39) -> 0 | AK39: =+AA39 -> 12 | AL39: =+AB39 -> 34 | AM39: =+IF($C39>=$F$5,1,0) -> 1 | AN39: =+$F$9*AM39 -> 0.135 | AO39: =+AM39*$F$10 -> 0.18 | AP39: =+G39 -> 4200 | AQ39: =+AT38 -> 8496.4014 | AR39: =+(AN39*AP39+AO39*(AP39/12))*AM39 -> 630 | AS39: =+AQ39*$F$12 -> 339.85606 | AT39: =+(AQ39+AR39+AS39) -> 9466.2574 | AV39: =+AK39 -> 12 | AW39: =+AL39 -> 34 | AX39: 1 | AY39: =+$F$9*AX39 -> 0.135 | AZ39: =+AX39*$F$10 -> 0.18 | BA39: =+G39 -> 4200 | BB39: =+BE38 -> 8496.4014 | BC39: =+(AY39*BA39+AZ39*(BA39/12))*AX39 -> 630 | BD39: =+BB39*$F$12 -> 339.85606 | BE39: =+(BB39+BC39+BD39) -> 9466.2574
B40: =+B39+1 -> 13 | C40: =+C39+1 -> 34 | D40: =+D39*(1+$F$18) -> 1 | E40: =+IF($C40>=$F$6,0,$F$19*D40) -> 700 | F40: =+IF($C40>=$F$6,0,$F$20) -> 6 | G40: =+E40*F40 -> 4200 | I40: =+I39+1 -> 13 | J40: =+C40 -> 34 | K40: =+IF(AL40<=$AF$11,1,0)*F40 -> 6 | L40: =+IF(AL40>$AF$11,0,IF(E40>500,500*F40,E40*F40)) -> 3000 | M40: =+IF(AL40>$AF$11,0,IF(G40-L40 <= 0,0,G40-L40)) -> 1200 | N40: =+IF($F$7<7,L40+M40,IF(AL40>$AF$11,0,IF($F$2=1,IF($J40<$F$5,IF(G40<=$F$16*12,G40,$F$16*12),G40),G40))) -> 4200 | O40: =+IFERROR(N40/K40,0) -> 700 | Q40: =+I40 -> 13 | R40: =+J40+1 -> 35 | S40: =+IF(R40<=$AF$11,1,0) -> 1 | T40: =+T39 -> 0.1 | U40: =+M40 -> 1200 | V40: =+Y39 -> 1803.0967 | W40: =+T40*U40*S40 -> 120 | X40: =+$U$23*V40 -> 72.123866 | Y40: =+(V40+W40+X40) -> 1995.2205 | AA40: =+B40 -> 13 | AB40: =+C40+1 -> 35 | AC40: =+IF(C40<$F$5,1,0) -> 0 | AD40: =+AD39 -> 0.15 | AE40: =+IF($F$2=1,IF(G40<=2500*12,G40,2500*12),G40) -> 4200 | AF40: =+AI39 -> 0 | AG40: =+AD40*AE40*$AC40 -> 0 | AH40: =+AF40*$F$11 -> 0 | AI40: =+(AF40+AG40+AH40) -> 0 | AK40: =+AA40 -> 13 | AL40: =+AB40 -> 35 | AM40: =+IF($C40>=$F$5,1,0) -> 1 | AN40: =+$F$9*AM40 -> 0.135 | AO40: =+AM40*$F$10 -> 0.18 | AP40: =+G40 -> 4200 | AQ40: =+AT39 -> 9466.2574 | AR40: =+(AN40*AP40+AO40*(AP40/12))*AM40 -> 630 | AS40: =+AQ40*$F$12 -> 378.6503 | AT40: =+(AQ40+AR40+AS40) -> 10474.908 | AV40: =+AK40 -> 13 | AW40: =+AL40 -> 35 | AX40: 1 | AY40: =+$F$9*AX40 -> 0.135 | AZ40: =+AX40*$F$10 -> 0.18 | BA40: =+G40 -> 4200 | BB40: =+BE39 -> 9466.2574 | BC40: =+(AY40*BA40+AZ40*(BA40/12))*AX40 -> 630 | BD40: =+BB40*$F$12 -> 378.6503 | BE40: =+(BB40+BC40+BD40) -> 10474.908
... B65: =+B64+1 -> 38 | C65: =+C64+1 -> 59 | D65: =+D64*(1+$F$18) -> 1 | E65: =+IF($C65>=$F$6,0,$F$19*D65) -> 700 | F65: =+IF($C65>=$F$6,0,$F$20) -> 6 | G65: =+E65*F65 -> 4200 | I65: =+I64+1 -> 38 | J65: =+C65 -> 59 | K65: =+IF(AL65<=$AF$11,1,0)*F65 -> 6 | L65: =+IF(AL65>$AF$11,0,IF(E65>500,500*F65,E65*F65)) -> 3000 | M65: =+IF(AL65>$AF$11,0,IF(G65-L65 <= 0,0,G65-L65)) -> 1200 | N65: =+IF($F$7<7,L65+M65,IF(AL65>$AF$11,0,IF($F$2=1,IF($J65<$F$5,IF(G65<=$F$16*12,G65,$F$16*12),G65),G65))) -> 4200 | O65: =+IFERROR(N65/K65,0) -> 700 | Q65: =+I65 -> 38 | R65: =+J65+1 -> 60 | S65: =+IF(R65<=$AF$11,1,0) -> 1 | T65: =+T64 -> 0.1 | U65: =+M65 -> 1200 | V65: =+Y64 -> 9804.2696 | W65: =+T65*U65*S65 -> 120 | X65: =+$U$23*V65 -> 392.17078 | Y65: =+(V65+W65+X65) -> 10316.44 | AA65: =+B65 -> 38 | AB65: =+C65+1 -> 60 | AC65: =+IF(C65<$F$5,1,0) -> 0 | AD65: =+AD64 -> 0.15 | AE65: =+IF($F$2=1,IF(G65<=2500*12,G65,2500*12),G65) -> 4200 | AF65: =+AI64 -> 0 | AG65: =+AD65*AE65*$AC65 -> 0 | AH65: =+AF65*$F$11 -> 0 | AI65: =+(AF65+AG65+AH65) -> 0 | AK65: =+AA65 -> 38 | AL65: =+AB65 -> 60 | AM65: =+IF($C65>=$F$5,1,0) -> 1 | AN65: =+$F$9*AM65 -> 0.135 | AO65: =+AM65*$F$10 -> 0.18 | AP65: =+G65 -> 4200 | AQ65: =+AT64 -> 51472.415 | AR65: =+(AN65*AP65+AO65*(AP65/12))*AM65 -> 630 | AS65: =+AQ65*$F$12 -> 2058.8966 | AT65: =+(AQ65+AR65+AS65) -> 54161.312 | AV65: =+AK65 -> 38 | AW65: =+AL65 -> 60 | AX65: 1 | AY65: =+$F$9*AX65 -> 0.135 | AZ65: =+AX65*$F$10 -> 0.18 | BA65: =+G65 -> 4200 | BB65: =+BE64 -> 51472.415 | BC65: =+(AY65*BA65+AZ65*(BA65/12))*AX65 -> 630 | BD65: =+BB65*$F$12 -> 2058.8966 | BE65: =+(BB65+BC65+BD65) -> 54161.312
...

Sheet calculo 25
B1: DATOS BASICOS | BH1: BENEFICIO DE JUBILACION CSS SEBD
B2: SISTEMA | F2: 1 | BH2: CUOTAS APORTADAS | BM2: =+SUM(K28:K76) -> 300
B3: SEXO | F3: =+salidaformulas!B2 -> M | Q3: MIXTO | AA3: CAPITALIZACIÓN SOLIDARIA | BH3: CUOTAS EN EXCESO A DENSIDAD MIN | BM3: =+IF(BM2>240,BM2-F13,0) -> 60
B4: EDAD ENTRADA | F4: =+salidaformulas!B3 -> 22 | I4: SOLIDARIO | BH4: TASA DE REEMPLAZO AJUSTADA SEBD LEY 51 | BM4: =IF(F7<=7,BN4,BN4*AF13) -> 0.6625 | BN4: =IF(AND(BM2>=180,BM2<240),($F$14+INT(BM3/12)*$F$15)*BM2/240,IF(BM2<180,0,($F$14+INT(BM3/12)*$F$15))) -> 0.6625
B5: EDAD ACTUAL DIA DE REFORMA | F5: =+F4 -> 22 | J5: Mej. Salario Anual | K5: Mej Salario Anual | S5: Mej. Salario Anual | T5: Mej Salario Anual | BH5: PENSION ANNUAL A RECIBIR | BM5: =+BM6*12 -> 3478.125
B6: EDAD DE JUBILACION | F6: =+salidaformulas!B4 -> 62 | I6: Mejores Años | J6: TOTAL | K6: Primer Pilar | R6: Mejores Años | S6: TOTAL | T6: Primer Pilar | BH6: PENSION MENSUAL A RECIBIR | BM6: =IF(BM2>=240,MAX(MAX(BL8:BL10),265),MAX(BL8:BL10)) -> 289.84375
B7: AÑOS PARA JUBILARSE | F7: =+F6-F5 -> 40 | I7: 1 | J7: =LARGE($G$28:$G$65,I7) -> 5250 | K7: =LARGE($L$28:$L$65,I7) -> 3750 | R7: 1 | S7: =+J7 -> 5250 | T7: =+K7 -> 3750 | BL7: PENSION | BM7: PROM. ANUAL | BN7: PROM.MENSUAL
B8: % CUOTA APLICADO ANTES VIGENCIA NVA LEY | F8: 0.15 | I8: 2 | J8: =LARGE($G$28:$G$65,I8) -> 5250 | K8: =LARGE($L$28:$L$65,I8) -> 3750 | R8: 2 | S8: =+J8 -> 5250 | T8: =+K8 -> 3750 | BH8: CALCULO DE LOS MEJORES 10 AÑOS | BL8: =+IF($BM$4*BM8/12>1500,1500,$BM$4*BM8/12) -> 289.84375 | BM8: {=+AVERAGE(LARGE($G$28:$G$76,ROW(INDIRECT("1:10"))))} -> 5250
B9: % CUOTA EMPLEADO EMPLEADOR NUEVA LEY | F9: 0.135 | I9: 3 | J9: =LARGE($G$28:$G$65,I9) -> 5250 | K9: =LARGE($L$28:$L$65,I9) -> 3750 | R9: 3 | S9: =+J9 -> 5250 | T9: =+K9 -> 3750 | BH9: CALCULO DE LOS MEJORES 15 AÑOS (300 CUOTAS Y PROM>=$2,000) | BL9: =+IF($BM$4*BM9/12>2000,2000,$BM$4*BM9/12) -> 0 | BM9: {=IF(AND(BM2>300,AVERAGE(LARGE($G$28:$G$76,ROW(INDIRECT("1:15"))))>=24000),AVERAGE(LARGE($G$28:$G$76,ROW(INDIRECT("1:15")))),0)} -> 0
B10: % XIII EMPLEADO EMPLEADOR NUEVA LEY | F10: 0.18 | I10: 4 | J10: =LARGE($G$28:$G$65,I10) -> 5250 | K10: =LARGE($L$28:$L$65,I10) -> 3750 | R10: 4 | S10: =+J10 -> 5250 | T10: =+K10 -> 3750 | AA10: SCGS-CUANDO VIENE DEL SEBD o SM | BH10: CALCULO DE LOS MEJORES 20 AÑOS (360 cuotas y prom>=$2,500) | BL10: =+IF($BM$4*BM10/12>2500,2500,$BM$4*BM10/12) -> 0 | BM10: {=IF(AND(BM2>360,AVERAGE(LARGE($G$28:$G$76,ROW(INDIRECT("1:20"))))>=30000),AVERAGE(LARGE($G$28:$G$76,ROW(INDIRECT("1:20")))),0)} -> 0
B11: TASA DE RETORNO INVERSIONES ANTES VIG LEY | F11: 0.04 | I11: 5 | J11: =LARGE($G$28:$G$65,I11) -> 5250 | K11: =LARGE($L$28:$L$65,I11) -> 3750 | R11: 5 | S11: =+J11 -> 5250 | T11: =+K11 -> 3750 | AA11: EDAD JUBILACION | AF11: =+F6 -> 62 | AK11: RESULTADO COMPARATIVO | AO11: MONTO | AP11: REEMPLAZO MEJ.AÑOS | BH11: TASA DE REEMPLAZO FINAL DE ESTE CALCULO | BM11: =+BM5/VLOOKUP(MAX(BL8:BL10),BL8:BM10,2,0) -> 0.6625
B12: TASA RETORNO INVERSIONES PROMEDIO | F12: 0.04 | I12: 6 | J12: =LARGE($G$28:$G$65,I12) -> 5250 | K12: =LARGE($L$28:$L$65,I12) -> 3750 | R12: 6 | S12: =+J12 -> 5250 | T12: =+K12 -> 3750 | AA12: FONDO AHORRADO COP ANTES VIGENCIA NVA LEY | AF12: =+VLOOKUP(AF11,$AB$28:$AI$76,8,FALSE) -> 0 | AG12: R | AK12: PENSION A RECIBIR DEL SEBD | AO12: =+L18 -> 289.84375 | AP12: =+AO12/(J16/12) -> 0.6625
A13: A | B13: DENSIDAD MINIMA DE CUOTAS LEY 51 | F13: 240 | I13: 7 | J13: =LARGE($G$28:$G$65,I13) -> 5250 | K13: =LARGE($L$28:$L$65,I13) -> 3750 | R13: 7 | S13: =+J13 -> 5250 | T13: =+K13 -> 3750 | W13: VP | X13: RA*ax | AA13: FACTOR DESCUENTO | AF13: =+IF(AND($B$20=1,$F$2<>1),100%,IF($F$3="M",VLOOKUP(AF11,descuento!$A$6:$B$32,2,FALSE),VLOOKUP(AF11,descuento!$C$6:$D$32,2,FALSE))) -> 1 | AK13: PENSION A RECIBIR SISTEMA MIXTO | AO13: =+U22 -> 280.5002 | AP13: =+AO13/(S17/12) -> 0.64114331 | AV13: FONDO TOTAL APLICABLE | BB13: =+VLOOKUP(AF11,$AW$28:$BE$76,9,FALSE) -> 74832.594 | BH13: BENEFICIO DEL SISTEMA MIXTO
